Workbook

Sheet Summary
J1: Drying | O1: Wetting | T1: Direct shear
A2: Samples | B2: Depth below surface [m] | C2: Slope angle [°] | D2: Plastic Limit (PL) | E2: Liquid Limit (LL) | F2: Soil Classification | G2: Specific Gravity (Gs) [-] | H2: rsat [g/cm^3] | I2: porosity [-] | J2: θsat [-] | K2: θr [-] | L2: a [1/cm] | M2: n [-] | N2: ksat [cm/s] | O2: θsat [-] | P2: θr [-] | Q2: a [1/cm] | R2: n [-] | S2: ksat [cm/s] | T2: f' [°] | U2: c' [kPa]
A3: UTU-1 z=0.m | B3: =0.92-0 -> 0.92 | C3: 42 | D3: =Atterberg!B19 -> 0.22212186 | E3: =Atterberg!B10 -> 0.2322 | F3: SM | G3: 2.6 | H3: =sat_density!B14 -> 1.9010846 | I3: =0.44 -> 0.44 | J3: =SWR_UTU0!B7 -> 0.44 | K3: =SWR_UTU0!B6 -> 0.1 | L3: =SWR_UTU0!B3 -> 0.04 | M3: =SWR_UTU0!B4 -> 1.64 | N3: =SWR_UTU0!B8 -> 0.000357 | O3: =SWR_UTU0!J7 -> 0.38 | P3: =SWR_UTU0!J6 -> 0.1 | Q3: =SWR_UTU0!J3 -> 0.04 | R3: =SWR_UTU0!J4 -> 1.5 | S3: =SWR_UTU0!J8 -> 0.00021 | T3: 40 | U3: 4.58
A4: UTU-1 z=0.35 m | B4: =0.92-0.35 -> 0.57 | C4: 42 | D4: =Atterberg!B39 -> 0.27277442 | E4: =Atterberg!C31 -> 0.324 | F4: SM | G4: 2.49 | H4: =sat_density!B26 -> 1.8969024 | I4: =SWR_UTU035!B7 -> 0.41 | J4: =I4 -> 0.41 | K4: =SWR_UTU035!J6 -> 0.089 | L4: =SWR_UTU035!B3 -> 0.08 | M4: =SWR_UTU035!B4 -> 1.47 | N4: =SWR_UTU035!B8 -> 0.00409 | O4: =SWR_UTU035!J7 -> 0.33 | P4: =SWR_UTU035!J6 -> 0.089 | Q4: =SWR_UTU035!J3 -> 0.08 | R4: =SWR_UTU035!J4 -> 1.4 | S4: =SWR_UTU035!J8 -> 6.89e-05 | T4: 34.8 | U4: 4.42
A5: UTU-7/8 B z = 0.55 m | B5: =0.92-0.55 -> 0.37 | C5: 42 | D5: no data | E5: no data | F5: no data | G5: no data | H5: no data | I5: no data | J5: no data | K5: no data | L5: no data | M5: no data | N5: no data | O5: no data | P5: no data | Q5: no data | R5: no data | S5: no data
A6: UTU-1 z=0.7m | B6: =0.92-0.7 -> 0.22 | C6: 42 | D6: =Atterberg!B48 -> 0.32799909 | E6: =Atterberg!C57 -> 0.391 | F6: SM | G6: 2.6 | H6: =sat_density!B40 -> 1.6671438 | I6: =J6 -> 0.46 | J6: =SWR_UTU07!B7 -> 0.46 | K6: =SWR_UTU07!B6 -> 0.1 | L6: =SWR_UTU07!B3 -> 0.042 | M6: =SWR_UTU07!B4 -> 1.586 | N6: =SWR_UTU07!B8 -> 0.0001 | O6: =SWR_UTU07!J7 -> 0.368 | P6: =SWR_UTU07!J6 -> 0.1 | Q6: =SWR_UTU07!J3 -> 0.042 | R6: =SWR_UTU07!J4 -> 1.55 | S6: =SWR_UTU07!J8 -> 4.79e-05 | T6: 53.9 | U6: 0.42
A7: ELT-1 z=0.15m | B7: =1.32-0.15 -> 1.17 | C7: 45 | D7: =Atterberg!B77 -> 0.38580772 | E7: =Atterberg!B69 -> 0.456 | F7: CL | G7: 2.57 | H7: =sat_density!B48 -> 1.7845347 | I7: =SWR_ELTz015!B7 -> 0.51 | J7: =SWR_ELTz015!B7 -> 0.51 | K7: =SWR_ELTz015!B6 -> 0.1 | L7: =SWR_ELTz015!B3 -> 0.019 | M7: =SWR_ELTz015!B4 -> 1.35 | N7: =SWR_ELTz015!B8 -> 7e-05 | O7: =SWR_ELTz015!J7 -> 0.46 | P7: =SWR_ELTz015!J6 -> 0.1 | Q7: =SWR_ELTz015!J3 -> 0.02 | R7: =SWR_ELTz015!J4 -> 1.39 | S7: =SWR_ELTz015!J8 -> 7.5e-06 | T7: 45.6 | U7: 2.29
A8: ELT-1 z=0.42m | B8: =1.32-0.42 -> 0.9 | C8: 45 | D8: =Atterberg!B98 -> 0.44336138 | E8: =Atterberg!B90 -> 0.6 | F8: MH | G8: 2.57 | H8: =sat_density!B60 -> 1.8063758 | I8: =SWR_ELTz042!B7 -> 0.5 | J8: =SWR_ELTz042!B7 -> 0.5 | K8: =SWR_ELTz042!B6 -> 0.1 | L8: =SWR_UTU0!B3 -> 0.04 | M8: =SWR_ELTz042!B4 -> 1.6 | N8: =SWR_ELTz042!B8 -> 3.59e-05 | O8: =SWR_ELTz042!J7 -> 0.46 | P8: =SWR_ELTz042!J6 -> 0.1 | Q8: =SWR_ELTz042!J3 -> 0.07 | R8: =SWR_ELTz042!J4 -> 1.39 | S8: =SWR_ELTz042!J8 -> 9.5e-06 | T8: 35.5 | U8: 0
A9: ELT-1 z=0.89m | B9: =1.32-0.89 -> 0.43 | C9: 45 | D9: =Atterberg!B117 -> 0.83487337 | E9: =Atterberg!B109 -> 1.1 | F9: OH | G9: 2.35 | H9: no data | I9: 0.52 | J9: no data | K9: no data | L9: no data | M9: no data | N9: no data | O9: no data | P9: no data | Q9: no data | R9: no data | S9: no data | T9: 34.9 | U9: 5.13
A10: ELT-1 remolded | B10: 0.9 | C10: 45 | N10: 0.00032
B11: z: height above bottom of soil pit | G11: rsat: saturated bulk density | I11: ksat: saturated hydraulic conductivity | M11: α, n: van Genuchten soil water retention parameters | S11: f': friction angle
A12: UTU-1 z=0m | F12: ELT-1 z=0.15m | I12: θsat: saturated water content | M12: θr : residual water content | S12: c': cohesion
A23: UTU-1 z=0.35m | F23: ELT-1 z=0.42m
A24: additional sample UTU-7/8 B collected at z=0.55 to supplement direct shear testing results (not pictured)
A33: UTU-1 z=0.7m | F33: ELT-1 z=0.89m | G33: Highly variable with depth

Sheet Atterberg
A1: UTU z=0m
A2: Item | B2: Test Number
B3: 1 | C3: 2 | D3: 3
A4: Can No. | B4: 1-utuz=0 | C4: 2-utuz=0 | D4: 3-utuz=0
A5: Mass of Can, M1 (g) | B5: 12.02 | C5: 12.15 | D5: 11.72
A6: Mass of can + moist soil, M2 (g) | B6: 18.87 | C6: 18.71 | D6: 22.24
A7: Mass of can + dry soil, M3 (g) | B7: 17.58 | C7: 17.47 | D7: 20.18
A8: Moisture content, w(%)=(M2-M3)/(M3-M1)*100 | B8: =(B6-B7)/(B7-B5) -> 0.23201439 | C8: =(C6-C7)/(C7-C5) -> 0.23308271 | D8: =(D6-D7)/(D7-D5) -> 0.24349882
A9: Number of Blows, N | B9: 28 | C9: 23 | D9: 16
A10: Liquid Limit | B10: 0.2322
A12: Item | B12: Test Number
B13: 1 | C13: 2 | D13: 3 | E13: 4
A14: Can No. | B14: 1-utuz=0 | C14: 2-utuz=0 | D14: 3-utuz=0 | E14: 4-utuz=0
A15: Mass of Can, M1 (g) | B15: 11.81 | C15: 11.48 | D15: 12.27 | E15: 12.28 | F15: =(23.4-23.2)/5 -> 0.04
A16: Mass of can + moist soil, M2 (g) | B16: 15.23 | C16: 14.43 | D16: 15.58 | E16: 15.56
A17: Mass of can + dry soil, M3 (g) | B17: 14.62 | C17: 13.86 | D17: 15.01 | E17: 14.96
A18: Moisture content, w(%)=(M2-M3)/(M3-M1)*100 | B18: =(B16-B17)/(B17-B15) -> 0.21708185 | C18: =(C16-C17)/(C17-C15) -> 0.2394958 | D18: =(D16-D17)/(D17-D15) -> 0.2080292 | E18: =(E16-E17)/(E17-E15) -> 0.2238806
A19: Plastic Limit | B19: =AVERAGE(B18:E18) -> 0.22212186
A23: UTU z=0.35m
A24: Liquid Limit Test
A25: Tail number | B25: 1 | C25: 2 | D25: 3
A26: Mass of Can (g) | B26: 12.03 | C26: 11.73 | D26: 12.76
A27: Mass of Can + Moist Soil (g) | B27: 20.54 | C27: 23.34 | D27: 26.21
A28: Mass of Can + Dry Soil (g) | B28: 18.5 | C28: 20.39 | D28: 22.85
A29: water content (%) | B29: =(B27-B28)/(B28-B26) -> 0.31530139 | C29: =(C27-C28)/(C28-C26) -> 0.34064665 | D29: =(D27-D28)/(D28-D26) -> 0.33300297
A30: Number of Blow | B30: 27 | C30: 17 | D30: 23
A31: LL= | C31: 0.324
A33: Plastic Limit Test
A34: Tail number | B34: 1 | C34: 2 | D34: 3
A35: Mass of Can (g) | B35: 11.96 | C35: 12.24 | D35: 32.83
A36: Mass of Can + Moist Soil (g) | B36: 16.05 | C36: 15.55 | D36: 37.36
A37: Mass of Can + Dry Soil (g) | B37: 15.13 | C37: 14.84 | D37: 36.39
A38: water content (%) | B38: =(B36-B37)/(B37-B35) -> 0.29022082 | C38: =(C36-C37)/(C37-C35) -> 0.27307692 | D38: =(D36-D37)/(D37-D35) -> 0.27247191
A39: PL | B39: =AVERAGE(C38:E38) -> 0.27277442
A41: UTU z=0.7m
A42: Plastic Limit Test
A43: Tail number | B43: 1 | C43: 2 | D43: 3
A44: Mass of Can (g) | B44: 11.99 | C44: 12.3 | D44: 16.95
A45: Mass of Can + Moist Soil (g) | B45: 18.64 | C45: 15.78 | D45: 26.48
A46: Mass of Can + Dry Soil (g) | B46: 17.07 | C46: 14.87 | D46: 24.27
...

Sheet PSD UTU z=0.0
B1: Sieve Analysis
A2: Sieve # | B2: Diameter (mm) | C2: Mass retained (g) | D2: % Finer | P2: Hydrometer Reading | Q2: L | R2: Hydrometer Reading | S2: L | T2: Hydrometer Reading | U2: L | V2: Hydrometer Reading | W2: L
A3: 10 | B3: 2 | C3: 4.57 | D3: =($C$10-C3)/$C$10 -> 0.98318307 | G3: Water viscosity | H3: A | I3: Ft | Q3: (cm) | S3: (cm) | U3: (cm) | W3: (cm)
A4: 40 | B4: 0.4 | C4: 117.53 | D4: =($C$10-C4-C3)/$C$10 -> 0.55068997 | G4: =0.000931*98.0665 -> 0.091299911 | H4: 0.0134 | I4: =-4.85+23*0.25 -> 0.9 | P4: 0 | Q4: 16.3 | R4: 13 | S4: 14.2 | T4: 26 | U4: 12 | V4: 39 | W4: 9.9
A5: 60 | B5: 0.25 | C5: 38.54 | D5: =($C$10-C5-C4-C3)/$C$10 -> 0.40886845 | P5: 1 | Q5: 16.1 | R5: 14 | S5: 14 | T5: 27 | U5: 11.9 | V5: 40 | W5: 9.7
A6: 80 | B6: 0.177 | C6: 17.01 | D6: =($C$10-C6-C5-C4-C3)/$C$10 -> 0.34627415 | P6: 2 | Q6: 16 | R6: 15 | S6: 13.8 | T6: 28 | U6: 11.7 | V6: 41 | W6: 9.6
A7: 100 | B7: 0.149 | C7: 7.64 | D7: =($C$10-C7-C6-C5-C4-C3)/$C$10 -> 0.31816007 | P7: 3 | Q7: 15.8 | R7: 16 | S7: 13.7 | T7: 29 | U7: 11.5 | V7: 42 | W7: 9.4
A8: 200 | B8: 0.075 | C8: 25.97 | D8: =($C$10-C8-C7-C6-C5-C4-C3)/$C$10 -> 0.2225943 | P8: 4 | Q8: 15.6 | R8: 17 | S8: 13.5 | T8: 30 | U8: 11.4 | V8: 43 | W8: 9.2
A9: Pan | C9: 60.49 | D9: =C9/$C$10 -> 0.2225943 | P9: 5 | Q9: 15.5 | R9: 18 | S9: 13.6 | T9: 31 | U9: 11.2 | V9: 44 | W9: 9.1
B10: Total mass | C10: =SUM(C3:C9) -> 271.75 | P10: 6 | Q10: 15.3 | R10: 19 | S10: 13.2 | T10: 32 | U10: 11.1 | V10: 45 | W10: 8.9
P11: 7 | Q11: 15.2 | R11: 20 | S11: 13 | T11: 33 | U11: 10.9 | V11: 46 | W11: 8.8
B12: Hydrometer test | P12: 8 | Q12: 15 | R12: 21 | S12: 12.9 | T12: 34 | U12: 10.7 | V12: 47 | W12: 8.6
B13: Hydrometer Reading | C13: L (cm) | D13: t (min) | E13: D (mm) | F13: Percentage Finer | P13: 9 | Q13: 14.8 | R13: 22 | S13: 12.7 | T13: 35 | U13: 10.6 | V13: 48 | W13: 8.4
B14: 30 | C14: 11.4 | D14: 2 | E14: =$H$4*SQRT(C14/D14) -> 0.031992062 | F14: =(B14+$I$4)*100*$H$4/60*$D$9 -> 0.15361232 | P14: 10 | Q14: 14.7 | R14: 23 | S14: 12.5 | T14: 36 | U14: 10.4 | V14: 49 | W14: 8.3
B15: 29 | C15: 11.5 | D15: 4 | E15: =$H$4*SQRT(C15/D15) -> 0.022720805 | F15: =(B15+$I$4)*100*$H$4/60*$D$9 -> 0.14864105 | P15: 11 | Q15: 14.5 | R15: 24 | S15: 12.4 | T15: 37 | U15: 10.2 | V15: 50 | W15: 8.1
B16: 26 | C16: =U4 -> 12 | D16: 8 | E16: =$H$4*SQRT(C16/D16) -> 0.016411581 | F16: =(B16+$I$4)*100*$H$4/60*$D$9 -> 0.13372723 | P16: 12 | Q16: 14.3 | R16: 25 | S16: 12.2 | T16: 38 | U16: 10.1 | V16: 51 | W16: 7.9
B17: 24 | C17: =S15 -> 12.4 | D17: 16 | E17: =$H$4*SQRT(C17/D17) -> 0.011796567 | F17: =(B17+$I$4)*100*$H$4/60*$D$9 -> 0.12378469
B18: 22 | C18: =S13 -> 12.7 | D18: 30 | E18: =$H$4*SQRT(C18/D18) -> 0.0087185855 | F18: =(B18+$I$4)*100*$H$4/60*$D$9 -> 0.11384214
B19: 20 | C19: =S11 -> 13 | D19: 60 | E19: =$H$4*SQRT(C19/D19) -> 0.0062373606 | F19: =(B19+$I$4)*100*$H$4/60*$D$9 -> 0.1038996
B20: 18 | C20: =S9 -> 13.6 | D20: 120 | E20: =$H$4*SQRT(C20/D20) -> 0.0045111122 | F20: =(B20+$I$4)*100*$H$4/60*$D$9 -> 0.093957052
B21: 17 | C21: =S8 -> 13.5 | D21: 240 | E21: =$H$4*SQRT(C21/D21) -> 0.003178089 | F21: =(B21+$I$4)*100*$H$4/60*$D$9 -> 0.08898578
B22: 15 | C22: =S6 -> 13.8 | D22: 480 | E22: =$H$4*SQRT(C22/D22) -> 0.0022720805 | F22: =(B22+$I$4)*100*$H$4/60*$D$9 -> 0.079043235
B23: 13 | C23: =S4 -> 14.2 | D23: =D22*3 -> 1440 | E23: =$H$4*SQRT(C23/D23) -> 0.0013306619 | F23: =(B23+$I$4)*100*$H$4/60*$D$9 -> 0.069100689
C25: Particle size class | D25: Percentage
C26: Gravel | D26: 0
C27: Sand | D27: =1-D8 -> 0.7774057
C28: Silt | D28: =1-D27-D26-D29 -> 0.1435943
C29: Clay | D29: 0.079
C30: Silty Sand

Sheet PSD UTU z=0.35
B2: Sieve Analysis
A3: Sieve # | B3: Diameter (mm) | C3: Mass retained (g) | D3: % Finer
A4: 4 | B4: 4.75 | C4: 2.65 | D4: =($C$12-C4)/$C$12 -> 0.99063439
A5: 10 | B5: 2 | C5: 7.11 | D5: =($C$12-C5-C4)/$C$12 -> 0.96550627
A6: 40 | B6: 0.4 | C6: 74.5 | D6: =($C$12-C6-C5-C4)/$C$12 -> 0.70220887
A7: 60 | B7: 0.25 | C7: 32.27 | D7: =($C$12-C7-C6-C5-C4)/$C$12 -> 0.58816045
A8: 80 | B8: 0.177 | C8: 22.89 | D8: =($C$12-C8-C7-C6-C5-C4)/$C$12 -> 0.50726277
A9: 100 | B9: 0.149 | C9: 3.93 | D9: =($C$12-C9-C8-C7-C6-C5-C4)/$C$12 -> 0.49337339
A10: 200 | B10: 0.075 | C10: 20.1 | D10: =($C$12-C10-C9-C8-C7-C6-C5-C4)/$C$12 -> 0.4223361
A11: Pan | C11: 119.5 | D11: 0.41
B12: Total mass | C12: =SUM(C4:C11) -> 282.95
B15: Hydrometer test | H15: Water viscosity | I15: A | J15: Ft | K15: Fm | L15: Hydrometer Reading | M15: L | N15: Hydrometer Reading | O15: L | P15: Hydrometer Reading | Q15: L | R15: Hydrometer Reading | S15: L
B16: Hydrometer Reading | C16: L (cm) | D16: t (min) | E16: D (mm) | F16: Percentage Finer | H16: =0.000931*98.0665 -> 0.091299911 | I16: 0.0134 | J16: =-4.85+23*0.25 -> 0.9 | K16: 1 | M16: (cm) | O16: (cm) | Q16: (cm) | S16: (cm)
B17: 44 | C17: =S23 -> 8.9 | D17: 2 | E17: =$I$16*SQRT(C17/D17) -> 0.028267331 | F17: =(B17+$J$16)*100*$I$16/60*'PSD UTU z=0.35'!$D$11 -> 0.41113433 | L17: 0 | M17: 16.3 | N17: 13 | O17: 14.2 | P17: 26 | Q17: 12 | R17: 39 | S17: 9.9
B18: 42 | C18: =S21 -> 9.2 | D18: 4 | E18: =$I$16*SQRT(C18/D18) -> 0.020322106 | F18: =(B18+$J$16)*100*$I$16/60*'PSD UTU z=0.35'!$D$11 -> 0.392821 | L18: 1 | M18: 16.1 | N18: 14 | O18: 14 | P18: 27 | Q18: 11.9 | R18: 40 | S18: 9.7
B19: 40 | C19: =S19 -> 9.6 | D19: 8 | E19: =$I$16*SQRT(C19/D19) -> 0.014678965 | F19: =(B19+$J$16)*100*$I$16/60*'PSD UTU z=0.35'!$D$11 -> 0.37450767 | L19: 2 | M19: 16 | N19: 15 | O19: 13.8 | P19: 28 | Q19: 11.7 | R19: 41 | S19: 9.6
B20: 36 | C20: =Q28 -> 10.2 | D20: 16 | E20: =$I$16*SQRT(C20/D20) -> 0.010699042 | F20: =(B20+$J$16)*100*$I$16/60*'PSD UTU z=0.35'!$D$11 -> 0.337881 | L20: 3 | M20: 15.8 | N20: 16 | O20: 13.7 | P20: 29 | Q20: 11.5 | R20: 42 | S20: 9.4
B21: 34 | C21: =Q26 -> 10.6 | D21: 30 | E21: =$I$16*SQRT(C21/D21) -> 0.0079652077 | F21: =(B21+$J$16)*100*$I$16/60*'PSD UTU z=0.35'!$D$11 -> 0.31956767 | L21: 4 | M21: 15.6 | N21: 17 | O21: 13.5 | P21: 30 | Q21: 11.4 | R21: 43 | S21: 9.2
B22: 30 | C22: =Q22 -> 11.2 | D22: 60 | E22: =$I$16*SQRT(C22/D22) -> 0.0057894617 | F22: =(B22+$J$16)*100*$I$16/60*'PSD UTU z=0.35'!$D$11 -> 0.282941 | L22: 5 | M22: 15.5 | N22: 18 | O22: 13.6 | P22: 31 | Q22: 11.2 | R22: 44 | S22: 9.1
B23: 27 | C23: =Q19 -> 11.7 | D23: 120 | E23: =$I$16*SQRT(C23/D23) -> 0.0041841487 | F23: =(B23+$J$16)*100*$I$16/60*'PSD UTU z=0.35'!$D$11 -> 0.255471 | L23: 6 | M23: 15.3 | N23: 19 | O23: 13.2 | P23: 32 | Q23: 11.1 | R23: 45 | S23: 8.9
B24: 25 | C24: =Q17 -> 12 | D24: 240 | E24: =$I$16*SQRT(C24/D24) -> 0.0029963311 | F24: =(B24+$J$16)*100*$I$16/60*'PSD UTU z=0.35'!$D$11 -> 0.23715767 | L24: 7 | M24: 15.2 | N24: 20 | O24: 13 | P24: 33 | Q24: 10.9 | R24: 46 | S24: 8.8
B25: 22 | C25: =O27 -> 12.5 | D25: 480 | E25: =$I$16*SQRT(C25/D25) -> 0.0021624157 | F25: =(B25+$J$16)*100*$I$16/60*'PSD UTU z=0.35'!$D$11 -> 0.20968767 | L25: 8 | M25: 15 | N25: 21 | O25: 12.9 | P25: 34 | Q25: 10.7 | R25: 47 | S25: 8.6
B26: 18 | C26: =O23 -> 13.2 | D26: =D25*3 -> 1440 | E26: =$I$16*SQRT(C26/D26) -> 0.0012829523 | F26: =(B26+$J$16)*100*$I$16/60*'PSD UTU z=0.35'!$D$11 -> 0.173061 | L26: 9 | M26: 14.8 | N26: 22 | O26: 12.7 | P26: 35 | Q26: 10.6 | R26: 48 | S26: 8.4
L27: 10 | M27: 14.7 | N27: 23 | O27: 12.5 | P27: 36 | Q27: 10.4 | R27: 49 | S27: 8.3
C28: Particle size class | D28: Percentage | L28: 11 | M28: 14.5 | N28: 24 | O28: 12.4 | P28: 37 | Q28: 10.2 | R28: 50 | S28: 8.1
C29: Gravel | D29: =1-D4 -> 0.0093656123 | L29: 12 | M29: 14.3 | N29: 25 | O29: 12.2 | P29: 38 | Q29: 10.1 | R29: 51 | S29: 7.9
C30: Sand | D30: =1-D10-D29 -> 0.56829829
C31: Silt | D31: =D10-D32 -> 0.2123361
C32: Clay | D32: 0.21 | E32: =SUM(D29:D32) -> 1
C33: Sandy Silty Clay
V34: diameter (mm)
V35: 4.75
V36: 2
V37: 0.4
V38: 0.25
V39: 0.177
V40: 0.149
V41: 0.075
V42: 0.0283

Sheet PSD UTU z=0.7
B1: Sieve Analysis
A2: Sieve # | B2: Diameter (mm) | C2: Mass retained (g) | D2: % Finer
A3: 4 | B3: 4.75 | C3: 0.19 | D3: =($C$11-C3)/$C$11 -> 0.99870041
A4: 10 | B4: 2 | C4: 2.41 | D4: =($C$11-C4-C3)/$C$11 -> 0.98221614
A5: 40 | B5: 0.4 | C5: 40.1 | D5: =($C$11-C5-C4-C3)/$C$11 -> 0.70793434
A6: 60 | B6: 0.25 | C6: 16.7 | D6: =($C$11-C6-C5-C4-C3)/$C$11 -> 0.59370725
A7: 80 | B7: 0.177 | C7: 9.17 | D7: =($C$11-C7-C6-C5-C4-C3)/$C$11 -> 0.53098495
A8: 100 | B8: 0.149 | C8: 3.67 | D8: =($C$11-C8-C7-C6-C5-C4-C3)/$C$11 -> 0.50588235
A9: 200 | B9: 0.074 | C9: 13.52 | D9: =($C$11-C9-SUM(C3:C8))/$C$11 -> 0.41340629
A10: Pan | C10: =C11-SUM(C3:C9) -> 60.44 | D10: =(C10)/$C$11 -> 0.41340629
B11: Total mass | C11: 146.2
C14: Hydrometer test | I14: Water viscosity | J14: A | K14: Ft | L14: Fm | M14: Hydrometer Reading | N14: L | O14: Hydrometer Reading | P14: L | Q14: Hydrometer Reading | R14: L | S14: Hydrometer Reading | T14: L
C15: Hydrometer Reading | D15: L (cm) | E15: t (min) | F15: D (mm) | G15: Percentage Finer | I15: =0.000931*98.0665 -> 0.091299911 | J15: 0.0134 | K15: =-4.85+23*0.25 -> 0.9 | L15: 1 | N15: (cm) | P15: (cm) | R15: (cm) | T15: (cm)
C16: 43 | D16: 9.1 | E16: 2 | F16: =$J$15*SQRT(D16/E16) -> 0.028583177 | G16: =(C16+$K$15)*100*$J$15/60*$D$10 -> 0.40531731 | M16: 0 | N16: 16.3 | O16: 13 | P16: 14.2 | Q16: 26 | R16: 12 | S16: 39 | T16: 9.9
C17: 39 | D17: 9.7 | E17: 4 | F17: =$J$15*SQRT(D17/E17) -> 0.020867031 | G17: =(C17+$K$15)*100*$J$15/60*$D$10 -> 0.36838635 | M17: 1 | N17: 16.1 | O17: 14 | P17: 14 | Q17: 27 | R17: 11.9 | S17: 40 | T17: 9.7
C18: 36 | D18: 10.2 | E18: 8 | F18: =$J$15*SQRT(D18/E18) -> 0.01513073 | G18: =(C18+$K$15)*100*$J$15/60*$D$10 -> 0.34068813 | M18: 2 | N18: 16 | O18: 15 | P18: 13.8 | Q18: 28 | R18: 11.7 | S18: 41 | T18: 9.6
C19: 34 | D19: 10.6 | E19: 16 | F19: =$J$15*SQRT(D19/E19) -> 0.01090681 | G19: =(C19+$K$15)*100*$J$15/60*$D$10 -> 0.32222264 | M19: 3 | N19: 15.8 | O19: 16 | P19: 13.7 | Q19: 29 | R19: 11.5 | S19: 42 | T19: 9.4
C20: 32 | D20: =R23 -> 10.9 | E20: 30 | F20: =$J$15*SQRT(D20/E20) -> 0.0080771365 | G20: =(C20+$K$15)*100*$J$15/60*$D$10 -> 0.30375716 | M20: 4 | N20: 15.6 | O20: 17 | P20: 13.5 | Q20: 30 | R20: 11.4 | S20: 43 | T20: 9.2
C21: 30 | D21: =R21 -> 11.2 | E21: 60 | F21: =$J$15*SQRT(D21/E21) -> 0.0057894617 | G21: =(C21+$K$15)*100*$J$15/60*$D$10 -> 0.28529168 | M21: 5 | N21: 15.5 | O21: 18 | P21: 13.6 | Q21: 31 | R21: 11.2 | S21: 44 | T21: 9.1
C22: 26 | D22: =R17 -> 11.9 | E22: 120 | F22: =$J$15*SQRT(D22/E22) -> 0.0042197591 | G22: =(C22+$K$15)*100*$J$15/60*$D$10 -> 0.24836072 | M22: 6 | N22: 15.3 | O22: 19 | P22: 13.2 | Q22: 32 | R22: 11.1 | S22: 45 | T22: 8.9
C23: 23 | D23: =P27 -> 12.4 | E23: 240 | F23: =$J$15*SQRT(D23/E23) -> 0.0030458606 | G23: =(C23+$K$15)*100*$J$15/60*$D$10 -> 0.2206625 | M23: 7 | N23: 15.2 | O23: 20 | P23: 13 | Q23: 33 | R23: 10.9 | S23: 46 | T23: 8.8
C24: 21 | D24: =P25 -> 12.7 | E24: 480 | F24: =$J$15*SQRT(D24/E24) -> 0.0021796464 | G24: =(C24+$K$15)*100*$J$15/60*$D$10 -> 0.20219702 | M24: 8 | N24: 15 | O24: 21 | P24: 12.9 | Q24: 34 | R24: 10.7 | S24: 47 | T24: 8.6
C25: 17 | D25: =P21 -> 13.6 | E25: =E24*3 -> 1440 | F25: =$J$15*SQRT(D25/E25) -> 0.0013022459 | G25: =(C25+$K$15)*100*$J$15/60*$D$10 -> 0.16526606 | M25: 9 | N25: 14.8 | O25: 22 | P25: 12.7 | Q25: 35 | R25: 10.6 | S25: 48 | T25: 8.4
M26: 10 | N26: 14.7 | O26: 23 | P26: 12.5 | Q26: 36 | R26: 10.4 | S26: 49 | T26: 8.3
E27: Particle size class | F27: Percentage | M27: 11 | N27: 14.5 | O27: 24 | P27: 12.4 | Q27: 37 | R27: 10.2 | S27: 50 | T27: 8.1
E28: Gravel | F28: =1-D3 -> 0.0012995896 | M28: 12 | N28: 14.3 | O28: 25 | P28: 12.2 | Q28: 38 | R28: 10.1 | S28: 51 | T28: 7.9
E29: Sand | F29: =1-F28-F30-F31 -> 0.58529412
E30: Silt | F30: =D9-F31 -> 0.21340629
E31: Clay | F31: 0.2
E32: Sandy Silty Clay
Y41: diameter (mm)
Y42: 4.75
Y43: 2
Y44: 0.4
Y45: 0.25
Y46: 0.177
Y47: 0.149
Y48: 0.074
Y49: 0.0286

Sheet PSD ELT z=0.15
B2: Coarse | C2: 66.4
B3: Fine | C3: 111.65
C7: Sieve Analysis
B8: Sieve # | C8: Diameter (mm) | D8: Mass retained (g) | E8: % Finer
C9: 18.85 | D9: 8.6 | E9: =($D$16-D9)/$D$16 -> 0.95169896
B10: 4 | C10: 4.75 | D10: 20.45 | E10: =($D$16-D10-D9)/$D$16 -> 0.83684358
B11: 10 | C11: 2 | D11: 8.09 | E11: =($D$16-D11-D10-D9)/$D$16 -> 0.79140691
B12: 40 | C12: 0.4 | D12: 13.23 | E12: =($D$16-D12-D11-D10-D9)/$D$16 -> 0.71710194
B13: 60 | C13: 0.25 | D13: 10.26 | E13: =($D$16-D13-D12-D11-D10-D9)/$D$16 -> 0.65947767
B14: 200 | C14: 0.075 | D14: =C2-SUM(D9:D13) -> 5.77 | E14: =($D$16-D14-D13-D12-D11-D10-D9)/$D$16 -> 0.62707105
B15: Pan | D15: 111.65 | E15: 0.6301
C16: Total mass | D16: =C3+C2 -> 178.05 | E16: 0.55
D18: Hydrometer test | J18: Water viscosity | K18: A | L18: Ft | M18: Fm | N18: Hydrometer Reading | O18: L | P18: Hydrometer Reading | Q18: L | R18: Hydrometer Reading | S18: L | T18: Hydrometer Reading | U18: L
D19: Hydrometer Reading | E19: L (cm) | F19: t (min) | G19: D (mm) | H19: Percentage Finer | J19: =0.000931*98.0665 -> 0.091299911 | K19: 0.0134 | L19: =-4.85+23*0.25 -> 0.9 | M19: 1 | O19: (cm) | Q19: (cm) | S19: (cm) | U19: (cm)
D20: 38 | E20: =U20 -> 9.9 | F20: 2 | G20: =$K$19*SQRT(E20/F20) -> 0.029813118 | H20: =(D20+$L$19)*100*$K$19/60*$E$15 -> 0.54740988 | N20: 0 | O20: 16.3 | P20: 13 | Q20: 14.2 | R20: 26 | S20: 12 | T20: 39 | U20: 9.9
D21: 36 | E21: =S31 -> 10.2 | F21: 4 | G21: =$K$19*SQRT(E21/F21) -> 0.021398084 | H21: =(D21+$L$19)*100*$K$19/60*$E$15 -> 0.51926541 | N21: 1 | O21: 16.1 | P21: 14 | Q21: 14 | R21: 27 | S21: 11.9 | T21: 40 | U21: 9.7
D22: 34 | E22: =S29 -> 10.6 | F22: 8 | G22: =$K$19*SQRT(E22/F22) -> 0.015424558 | H22: =(D22+$L$19)*100*$K$19/60*$E$15 -> 0.49112094 | N22: 2 | O22: 16 | P22: 15 | Q22: 13.8 | R22: 28 | S22: 11.7 | T22: 41 | U22: 9.6
D23: 31 | E23: =S26 -> 11.1 | F23: 16 | G23: =$K$19*SQRT(E23/F23) -> 0.011161082 | H23: =(D23+$L$19)*100*$K$19/60*$E$15 -> 0.44890424 | N23: 3 | O23: 15.8 | P23: 16 | Q23: 13.7 | R23: 29 | S23: 11.5 | T23: 42 | U23: 9.4
D24: 29 | E24: =S24 -> 11.4 | F24: 30 | G24: =$K$19*SQRT(E24/F24) -> 0.0082603148 | H24: =(D24+$L$19)*100*$K$19/60*$E$15 -> 0.42075978 | N24: 4 | O24: 15.6 | P24: 17 | Q24: 13.5 | R24: 30 | S24: 11.4 | T24: 43 | U24: 9.2
D25: 26 | E25: =S21 -> 11.9 | F25: 60 | G25: =$K$19*SQRT(E25/F25) -> 0.0059676405 | H25: =(D25+$L$19)*100*$K$19/60*$E$15 -> 0.37854308 | N25: 5 | O25: 15.5 | P25: 18 | Q25: 13.6 | R25: 31 | S25: 11.2 | T25: 44 | U25: 9.1
D26: 24 | E26: =Q32 -> 12.2 | F26: 120 | G26: =$K$19*SQRT(E26/F26) -> 0.0042726182 | H26: =(D26+$L$19)*100*$K$19/60*$E$15 -> 0.35039861 | N26: 6 | O26: 15.3 | P26: 19 | Q26: 13.2 | R26: 32 | S26: 11.1 | T26: 45 | U26: 8.9
D27: 21 | E27: =Q29 -> 12.7 | F27: 240 | G27: =$K$19*SQRT(E27/F27) -> 0.0030824855 | H27: =(D27+$L$19)*100*$K$19/60*$E$15 -> 0.30818191 | N27: 7 | O27: 15.2 | P27: 20 | Q27: 13 | R27: 33 | S27: 10.9 | T27: 46 | U27: 8.8
D28: 19 | E28: =Q27 -> 13 | F28: 480 | G28: =$K$19*SQRT(E28/F28) -> 0.00220524 | H28: =(D28+$L$19)*100*$K$19/60*$E$15 -> 0.28003744 | N28: 8 | O28: 15 | P28: 21 | Q28: 12.9 | R28: 34 | S28: 10.7 | T28: 47 | U28: 8.6
D29: 16 | E29: =Q24 -> 13.5 | F29: =F28*3 -> 1440 | G29: =$K$19*SQRT(E29/F29) -> 0.0012974494 | H29: =(D29+$L$19)*100*$K$19/60*$E$15 -> 0.23782074 | N29: 9 | O29: 14.8 | P29: 22 | Q29: 12.7 | R29: 35 | S29: 10.6 | T29: 48 | U29: 8.4
N30: 10 | O30: 14.7 | P30: 23 | Q30: 12.5 | R30: 36 | S30: 10.4 | T30: 49 | U30: 8.3
F31: Particle size class | G31: Percentage | N31: 11 | O31: 14.5 | P31: 24 | Q31: 12.4 | R31: 37 | S31: 10.2 | T31: 50 | U31: 8.1
F32: Gravel | G32: =1-E10 -> 0.16315642 | N32: 12 | O32: 14.3 | P32: 25 | Q32: 12.2 | R32: 38 | S32: 10.1 | T32: 51 | U32: 7.9
F33: Sand | G33: =1-E15-G32 -> 0.20674358
F34: Silt | G34: =E14-G35 -> 0.34707105
F35: Clay | G35: 0.28 | H35: =SUM(G32:G35) -> 0.99697105
F36: Sandy Silty Clay
W47: diameter (mm)
W48: 18.85
W49: 4.75
W50: 2
W51: 0.4
W52: 0.25
W53: 0.075
W54: 0.074
W55: =G20 -> 0.029813118

Sheet PSD ELT z=0.42 
B2: Coarse | C2: 31.1
B3: Fine | C3: 32.4
B5: Sieve Analysis
A6: Sieve # | B6: Diameter (mm) | C6: Mass retained (g) | D6: % Finer
B7: 18.85 | C7: 7.81 | D7: =($C$14-C7)/$C$14 -> 0.87700787
A8: 4 | B8: 4.75 | C8: 13.22 | D8: =($C$14-C8-C7)/$C$14 -> 0.6688189
A9: 10 | B9: 2 | C9: 1.41 | D9: =($C$14-C9-C8-C7)/$C$14 -> 0.64661417
A10: 40 | B10: 0.4 | C10: 1.49 | D10: =($C$14-C10-C9-C8-C7)/$C$14 -> 0.62314961
A11: 60 | B11: 0.25 | C11: 1.01 | D11: =($C$14-C11-C10-C9-C8-C7)/$C$14 -> 0.60724409
A12: 200 | B12: 0.074 | C12: =C2-SUM(C7:C11) -> 6.16 | D12: =($C$14-C12-C11-C10-C9-C8-C7)/$C$14 -> 0.51023622
A13: Pan | C13: 32.4 | D13: =C13/C14 -> 0.51023622
B14: Total mass | C14: =C2+C3 -> 63.5 | D14: 0.443
C18: Particle size class | D18: Percentage | G18: Hydrometer test
C19: Gravel | D19: =1-D8 -> 0.3311811 | G19: Hydrometer Reading | H19: L (cm) | I19: t (min) | J19: D (mm) | K19: Percentage Finer
C20: Sand | D20: =1-D19-D13 -> 0.15858268 | G20: 38 | H20: 9.9 | I20: 2 | J20: 0.029813118 | K20: 0.443071
C21: Silt | D21: =D12-D22 -> 0.29023622 | G21: 36 | H21: 10.2 | I21: 4 | J21: 0.021398084 | K21: 0.420291
C22: Clay | D22: 0.22 | E22: =SUM(D19:D22) -> 1 | G22: 34 | H22: 10.6 | I22: 8 | J22: 0.015424558 | K22: 0.397511
C23: Sandy Silty Clay | G23: 31 | H23: 11.1 | I23: 16 | J23: 0.011161082 | K23: 0.363341
G24: 29 | H24: 11.4 | I24: 30 | J24: 0.0082603148 | K24: 0.340561
G25: 26 | H25: 11.9 | I25: 60 | J25: 0.0059676405 | K25: 0.306391
G26: 24 | H26: 12.2 | I26: 120 | J26: 0.0042726182 | K26: 0.283611
G27: 21 | H27: 12.7 | I27: 240 | J27: 0.0030824855 | K27: 0.249441
G28: 19 | H28: 13 | I28: 480 | J28: 0.00220524 | K28: 0.226661
G29: 16 | H29: 13.5 | I29: 1440 | J29: 0.0012974494 | K29: 0.192491
Q44: diameter (mm)
Q45: 18.85
Q46: 4.75
Q47: 2
Q48: 0.4
Q49: 0.25
Q50: 0.074
Q51: 0.074
Q52: =J20 -> 0.029813118

Sheet PSD ELT z=0.82
B2: Coarse | C2: 0.1
B3: Fine | C3: 0.9
D8: Hydrometer test | J8: Water viscosity | K8: A | L8: Ft | M8: Fm | N8: Hydrometer Reading | O8: L | P8: Hydrometer Reading | Q8: L | R8: Hydrometer Reading | S8: L | T8: Hydrometer Reading | U8: L
D9: Hydrometer Reading | E9: L (cm) | F9: t (min) | G9: D (mm) | H9: Percentage Finer | J9: =0.000931*98.0665 -> 0.091299911 | K9: 0.0134 | L9: =-4.85+23*0.25 -> 0.9 | M9: 1 | O9: (cm) | Q9: (cm) | S9: (cm) | U9: (cm)
D10: 29 | E10: =S13 -> 11.5 | F10: 2 | G10: =$K$9*SQRT(E10/F10) -> 0.032132071 | H10: =(D10+$L$9)*100*$K$9/38*0.9 -> 0.94893158 | N10: 0 | O10: 16.3 | P10: 13 | Q10: 14.2 | R10: 26 | S10: 12 | T10: 39 | U10: 9.9
D11: 28 | E11: =S12 -> 11.7 | F11: 4 | G11: =$K$9*SQRT(E11/F11) -> 0.022917526 | H11: =(D11+$L$9)*100*$K$9/38*0.9 -> 0.91719474 | N11: 1 | O11: 16.1 | P11: 14 | Q11: 14 | R11: 27 | S11: 11.9 | T11: 40 | U11: 9.7
D12: 28 | E12: =S12 -> 11.7 | F12: 8 | G12: =$K$9*SQRT(E12/F12) -> 0.016205138 | H12: =(D12+$L$9)*100*$K$9/38*0.9 -> 0.91719474 | N12: 2 | O12: 16 | P12: 15 | Q12: 13.8 | R12: 28 | S12: 11.7 | T12: 41 | U12: 9.6
D13: 27 | E13: =S11 -> 11.9 | F13: 16 | G13: =$K$9*SQRT(E13/F13) -> 0.011556286 | H13: =(D13+$L$9)*100*$K$9/38*0.9 -> 0.88545789 | N13: 3 | O13: 15.8 | P13: 16 | Q13: 13.7 | R13: 29 | S13: 11.5 | T13: 42 | U13: 9.4
D14: 24 | E14: =Q21 -> 12.4 | F14: 30 | G14: =$K$9*SQRT(E14/F14) -> 0.0086149947 | H14: =(D14+$L$9)*100*$K$9/38*0.9 -> 0.79024737 | N14: 4 | O14: 15.6 | P14: 17 | Q14: 13.5 | R14: 30 | S14: 11.4 | T14: 43 | U14: 9.2
D15: 22 | E15: =Q19 -> 12.7 | F15: 60 | G15: =$K$9*SQRT(E15/F15) -> 0.0061649709 | H15: =(D15+$L$9)*100*$K$9/38*0.9 -> 0.72677368 | N15: 5 | O15: 15.5 | P15: 18 | Q15: 13.6 | R15: 31 | S15: 11.2 | T15: 44 | U15: 9.1
D16: 20 | E16: =Q17 -> 13 | F16: 120 | G16: =$K$9*SQRT(E16/F16) -> 0.0044104799 | H16: =(D16+$L$9)*100*$K$9/38*0.9 -> 0.6633 | N16: 6 | O16: 15.3 | P16: 19 | Q16: 13.2 | R16: 32 | S16: 11.1 | T16: 45 | U16: 8.9
D17: 18 | E17: =Q15 -> 13.6 | F17: 240 | G17: =$K$9*SQRT(E17/F17) -> 0.003189838 | H17: =(D17+$L$9)*100*$K$9/38*0.9 -> 0.59982632 | N17: 7 | O17: 15.2 | P17: 20 | Q17: 13 | R17: 33 | S17: 10.9 | T17: 46 | U17: 8.8
D18: 17 | E18: =Q14 -> 13.5 | F18: 480 | G18: =$K$9*SQRT(E18/F18) -> 0.0022472483 | H18: =(D18+$L$9)*100*$K$9/38*0.9 -> 0.56808947 | N18: 8 | O18: 15 | P18: 21 | Q18: 12.9 | R18: 34 | S18: 10.7 | T18: 47 | U18: 8.6
D19: 14 | E19: =Q11 -> 14 | F19: =F18*3 -> 1440 | G19: =$K$9*SQRT(E19/F19) -> 0.0013212578 | H19: =(D19+$L$9)*100*$K$9/38*0.9 -> 0.47287895 | N19: 9 | O19: 14.8 | P19: 22 | Q19: 12.7 | R19: 35 | S19: 10.6 | T19: 48 | U19: 8.4
N20: 10 | O20: 14.7 | P20: 23 | Q20: 12.5 | R20: 36 | S20: 10.4 | T20: 49 | U20: 8.3
N21: 11 | O21: 14.5 | P21: 24 | Q21: 12.4 | R21: 37 | S21: 10.2 | T21: 50 | U21: 8.1
N22: 12 | O22: 14.3 | P22: 25 | Q22: 12.2 | R22: 38 | S22: 10.1 | T22: 51 | U22: 7.9

Sheet sat_density
A1: Saturated bulk density, | B1: rsat [g/cm^3]
A3: UTU-1 z=0m
A4: h (cm) | B4: 2.82
A5: D (cm) | B5: 6.13
A6: Area (m^2) | B6: =(PI()*B5^2)*0.0001/4 -> 0.0029512828
A7: Volume (cc) | B7: =(B4*PI()*B5^2)/4 -> 83.226176
A10: mass c= | B10: 110.71
A11: mass c+wet= | B11: 268.93
A12: mass c+dry | B12: 233.79
A13: w= | B13: =(B11-B12)/(B12-B10) -> 0.28550536
A14: sat density | B14: =(B11-B10)/B7 -> 1.9010846
A16: UTU-1 z=0.35m
A17: mass c (g)= | B17: 156.7
A18: mass c+wet (g)= | B18: 337.8
A19: moist soil (g)= | B19: =B18-B17 -> 181.1
A21: Volume | B21: =B22*B23 -> 103.88516
A22: Area | B22: =PI()*0.25*6.13^2 -> 29.512828
A23: height= | B23: =6.62-3.1 -> 3.52
A24: mass sat= | B24: 197.06
A25: mass dry= | B25: =303.8-B17 -> 147.1
A26: sat density | B26: =B24/B21 -> 1.8969024
A28: UTU-1 z=0.7m
A29: Mass in situ (g)= | B29: 125.51
A30: h (cm) | B30: 2.82
A31: D (cm) | B31: 6.13
A32: Area (m^2) | B32: =(PI()*B31^2)*0.0001/4 -> 0.0029512828
A33: Volume (cc) | B33: =(B30*PI()*B31^2)/4 -> 83.226176
A34: total density (g/cc) | B34: =B29/B33 -> 1.5080592
A36: mass c= | B36: 126.55
A37: mass c+wet= | B37: 265.3
A38: mass c+dry | B38: 219.14
A39: w= | B39: =(B37-B38)/(B38-B36) -> 0.49854196
A40: sat density | B40: =(B37-B36)/B33 -> 1.6671438
A42: ELT-1 z=0.15m
A43: Volume | B43: =B44*B45 -> 88.538485
A44: Area | B44: =PI()*0.25*6.13^2 -> 29.512828
A45: height= | B45: 3
A46: mass sat= | B46: 158
A47: mass dry= | B47: 112
A48: sat density | B48: =B46/B43 -> 1.7845347
...

Sheet Direct_shear_ELT&UTU
A1: Total stress due to porous stone, loading cap, and selfweight of soil (kPa)= | E1: =0.284+0.769 -> 1.053
A2: Pore water pressure (kPa)= | E2: 0.04
A3: Utuado | B3: Slope angle = 42degrees
A5: Sample | B5: Depth from surface (m) | C5: Total Normal stress (kPa) | D5: Effective normal stress (kPa) | E5: Shear stress (kPa) | F5: c' (kPa) | G5: phi' (deg) | H5: Sample
A6: UTU-1 z=0.0m | B6: 0.92 | C6: 4.06944 | D6: =C6-$E$2 -> 4.02944 | E6: 8.52264 | F6: 4.58 | G6: =ATAN(0.84)*(180/PI()) -> 40.030259 | H6: undisturbed
C7: 7.038 | D7: =C7-$E$2 -> 6.998 | E7: 9.67176 | H7: undisturbed
C8: 13.023 | D8: =C8-$E$2 -> 12.983 | E8: 15.8004 | H8: undisturbed
A9: UTU-1 z=0.35m | B9: 0.57 | C9: 0.2 | D9: 0.172 | E9: 1.125 | H9: undisturbed
C10: 3.06396 | D10: =C10-$E$2 -> 3.02396 | E10: 7.75656 | F10: 4.42 | G10: =ATAN(0.695)*(180/PI()) -> 34.799301 | H10: undisturbed
C11: 4.21308 | D11: =C11-$E$2 -> 4.17308 | E11: 10.0548 | H11: undisturbed
C12: 11.05992 | D12: =C12-$E$2 -> 11.01992 | E12: 14.74704 | H12: undisturbed
C13: 20.205 | D13: =C13-$E$2 -> 20.165 | E13: 17.33256 | H13: disturbed
C14: 40 | D14: 39.85 | E14: 32.44 | H14: undisturbed
C15: 60 | D15: 59.85 | E15: 43.42 | H15: undisturbed
C16: 120 | D16: 119.85 | E16: 86.6049 | H16: undisturbed
A17: UTU-7-B and UTU-8-B z=0.55m | C17: =D17+$E$2 -> 0.2115558 | D17: 0.1715558 | E17: 1.08 | H17: undisturbed
A18: (similar to UTU-1, z=0.35m) | C18: =D18+$E$2 -> 0.9805558 | D18: 0.9405558 | E18: 1.77 | H18: undisturbed
C19: =D19+$E$2 -> 1.9805558 | D19: 1.9405558 | E19: 3.195 | H19: undisturbed
C20: =D20+$E$2 -> 4.9805558 | D20: 4.9405558 | E20: 5.374 | H20: undisturbed
C21: =D21+$E$2 -> 6.9805558 | D21: 6.9405558 | E21: 4.288 | H21: undisturbed
C22: =D22+$E$2 -> 15.980556 | D22: 15.940556 | E22: 15.314 | H22: undisturbed
C23: =D23+$E$2 -> 30.980556 | D23: 30.940556 | E23: 25.029 | H23: undisturbed
C24: =D24+$E$2 -> 60.980556 | D24: 60.940556 | E24: 52.339 | H24: undisturbed
A25: UTU-1 z=0.7m | B25: =0.92-0.7 -> 0.22 | C25: 7.038 | D25: =C25-$E$2 -> 6.998 | E25: 10.38996 | F25: 0.42 | G25: =ATAN(1.37)*(180/PI()) -> 53.873284 | H25: undisturbed
C26: 4.06944 | D26: =C26-$E$2 -> 4.02944 | E26: 5.0274 | H26: undisturbed
C27: 2.05848 | D27: =C27-$E$2 -> 2.01848 | E27: 3.73464 | H27: undisturbed
A103: Total stress due to porous stone, loading cap, and selfweight of soil (kPa)= | E103: =0.284+0.769 -> 1.053
A104: Pore water pressure (kPa)= | E104: 0.04
A105: El Toro | B105: Slope angle = 45degrees | C105: These samples had roots and some cobbles, so the tested samples were disturbed.
C106: Total
A107: Sample | B107: Depth from surface (m) | C107: Total Normal stress kPa | D107: Effective normal stress (kPa) | E107: Shear stress kPa | F107: c' (kPa) | G107: phi' (deg) | H107: Sample
A108: ELT-1 z=0.89m | B108: 0.43 | C108: 3.06396 | D108: =C108-E104 -> 3.02396 | E108: 7.27776 | F108: 5.13 | G108: =ATAN(0.6984)*(180/PI()) -> 34.930448 | H108: disturbed
C109: 5.07492 | D109: =C109-E105 -> 5.07492 | E109: 8.6184 | H109: disturbed
C110: 8.04348 | D110: =C110-E106 -> 8.04348 | E110: 10.773 | H110: disturbed
C111: 0.2 | D111: 0.2 | E111: 2.315 | H111: Undisturbed
C112: 1 | D112: 0.85 | E112: 2.087 | H112: Undisturbed
A113: ELT-1 z=0.42m | B113: 0.9 | C113: 4.21308 | D113: =C113-$E$104 -> 4.17308 | E113: 6.17652 | F113: 0 | G113: =ATAN(0.7144)*(180/PI()) -> 35.542013 | H113: disturbed
C114: 20 | D114: 19.85 | E114: 15.93 | H114: Undisturbed
C115: 40 | D115: 39.85 | E115: 32.3 | H115: Undisturbed
C116: 50 | D116: 49.85 | E116: 39.356 | H116: disturbed
...

Sheet Falling_head
B2: D1. Falling head test: saturated remolded ELT sample which does not contain any particles > 5mm.
B3: Diameter of soil specimen
B5: Area of soil specimen
B7: Length of soil specimen
B9: Beginning head position
B11: Ending head position
B13: Time:
B15: Flow volume:
B17: According to falling head formula

Sheet TRIM
A1: Utuado
A3: Samples
A4: UTU-1 z=0.7m
A5: Gs= | B5: 2.6
A6: mass c (g)= | B6: 168.69
A7: mass c+wet (g)= | B7: 265.3
A8: moist soil (g)= | B8: =B7-B6 -> 96.61
A9: in situ w= | B9: =(95.88-84.88)/(84.88-39.04) -> 0.2399651
A10: dry soil (g)= | B10: =B8/(1+B9) -> 77.913483
A11: porosity small sample | B11: =1-(45.884/(B5*1*0.25*PI()*6.13^2)) -> 0.40203317
A12: porosity TRIM
A13: Volume | B13: =B14*B15 -> 92.080024
A14: Area | B14: =PI()*0.25*6.13^2 -> 29.512828
A15: height= | B15: =6.62-3.5 -> 3.12
A16: mass sat= | B16: =325.9-154.6 -> 171.3
A17: mass dry= | B17: =283.5-154.6 -> 128.9 | D17: =B16/B13 -> 1.8603383
A18: porosity | B18: =1-(B17/(B5*B13)) -> 0.46158873 | C18: =(B16-B17)/B13 -> 0.46046904
A19: Volume water initial | B19: =B18*B13 -> 42.503101 | C19: =C18*B13 -> 42.4
A21: UTU-1 z=0.35m
A22: Gs= | B22: 2.4
A23: mass c (g)= | B23: 156.7
A24: mass c+wet (g)= | B24: 337.8
A25: moist soil (g)= | B25: =B24-B23 -> 181.1
A27: Volume | B27: =B28*B29 -> 103.88516
A28: Area | B28: =PI()*0.25*6.13^2 -> 29.512828
A29: height= | B29: =6.62-3.1 -> 3.52
A30: mass sat= | B30: 197.06
A31: mass dry= | B31: =303.8-B23 -> 147.1 | D31: =B30/B27 -> 1.8969024
A32: porosity | B32: =1-(B31/(B22*B27)) -> 0.41000554 | C32: =(B30-B31)/B27 -> 0.48091568
A33: Volume water initial | B33: =B32*B27 -> 42.593489 | C33: =C32*B27 -> 49.96
A35: UTU-1 z=0.0m
A36: Gs= | B36: 2.6
A37: mass c (g)= | B37: 156.7
A38: mass c+wet (g)= | B38: 268.93
A39: dry soil (g)= | B39: 233.79
A41: Volume | B41: =B42*B43 -> 82.045663
A42: Area | B42: =PI()*0.25*6.13^2 -> 29.512828
A43: height= | B43: =6.62-3.84 -> 2.78
A44: mass sat= | B44: =306.8-B37 -> 150.1
A45: mass dry= | B45: =270.45-B37 -> 113.75
...

Sheet SWR_UTU07
A1: Van Genuchten parameters | I1: Van Genuchten parameters
A2: DRYING | I2: WETTING
A3: a (1/cm) = | B3: 0.042 | C3: =B3*10.19 -> 0.42798 | D3: =1/C3 -> 2.3365578 | I3: a = | J3: 0.042 | K3: =J3*10.19 -> 0.42798 | L3: =1/K3 -> 2.3365578
A4: n = | B4: 1.586 | I4: n = | J4: 1.55
A5: m= | B5: =1-1/B4 -> 0.36948298 | I5: m= | J5: =1-1/J4 -> 0.35483871
A6: qr = | B6: 0.1 | I6: qr = | J6: 0.1
A7: qs = | B7: 0.46 | I7: qs = | J7: 0.368
A8: ksat (cm/sec)= | B8: 0.0001 | I8: ksat (cm/sec)= | J8: 4.79e-05
A9: l= | B9: 0.5 | I9: l= | J9: 0.5
A11: HCCC obtained with Van Genuchten-Mualem model | I11: HCCC obtained with Van Genuchten-Mualem model
A13: Suction (cm) | B13: Suction (kPa) | C13: q | D13: Se | E13: k (cm/s) | G13: Suction stress (kPa) | I13: Suction (cm) | J13: Suction (kPa) | K13: q | L13: Se | M13: k (cm/s) | O13: Suction stress (kPa)
A14: 1 | B14: =0.098967*A14 -> 0.098967 | C14: =$B$6+(($B$7-$B$6)/(1+($B$3*A14)^$B$4)^$B$5) -> 0.45913219 | D14: =(C14-$B$6)/($B$7-$B$6) -> 0.9975894 | E14: =$B$8*D14^$B$9*(1-(1-D14^(1/$B$5))^$B$5)^2 -> 7.1205092e-05 | F14: =$B$8*((1-(($B$3*A14)^($B$4-1))*(1+($B$3*A14)^$B$4)^(-1+1/$B$4))^2)/(1+($B$3*A14)^$B$4)^(0.5-(1/(2*$B$4))) -> 7.1205092e-05 | G14: =D14*B14 -> 0.09872843 | I14: 1 | J14: =0.098967*I14 -> 0.098967 | K14: =$J$6+(($J$7-$J$6)/(1+($J$3*I14)^$J$4)^$J$5) -> 0.3673049 | L14: =(K14-$J$6)/($J$7-$J$6) -> 0.99740634 | M14: =$J$8*L14^$J$9*(1-(1-L14^(1/$J$5))^$J$5)^2 -> 3.2603431e-05 | N14: =$J$8*((1-(($J$3*I14)^($J$4-1))*(1+($J$3*I14)^$J$4)^(-1+1/$J$4))^2)/(1+($J$3*I14)^$J$4)^(0.5-(1/(2*$J$4))) -> 3.2603431e-05 | O14: =L14*J14 -> 0.098710313
A15: 2 | B15: =0.098967*A15 -> 0.197934 | C15: =$B$6+(($B$7-$B$6)/(1+($B$3*A15)^$B$4)^$B$5) -> 0.45741772 | D15: =(C15-$B$6)/($B$7-$B$6) -> 0.99282699 | E15: =$B$8*D15^$B$9*(1-(1-D15^(1/$B$5))^$B$5)^2 -> 5.8687569e-05 | F15: =$B$8*((1-(($B$3*A15)^($B$4-1))*(1+($B$3*A15)^$B$4)^(-1+1/$B$4))^2)/(1+($B$3*A15)^$B$4)^(0.5-(1/(2*$B$4))) -> 5.8687569e-05 | G15: =D15*B15 -> 0.19651422 | I15: 2 | J15: =0.098967*I15 -> 0.197934 | K15: =$J$6+(($J$7-$J$6)/(1+($J$3*I15)^$J$4)^$J$5) -> 0.36598381 | L15: =(K15-$J$6)/($J$7-$J$6) -> 0.99247692 | M15: =$J$8*L15^$J$9*(1-(1-L15^(1/$J$5))^$J$5)^2 -> 2.6546647e-05 | N15: =$J$8*((1-(($J$3*I15)^($J$4-1))*(1+($J$3*I15)^$J$4)^(-1+1/$J$4))^2)/(1+($J$3*I15)^$J$4)^(0.5-(1/(2*$J$4))) -> 2.6546647e-05 | O15: =L15*J15 -> 0.19644493
A16: 4 | B16: =0.098967*A16 -> 0.395868 | C16: =$B$6+(($B$7-$B$6)/(1+($B$3*A16)^$B$4)^$B$5) -> 0.45244699 | D16: =(C16-$B$6)/($B$7-$B$6) -> 0.97901942 | E16: =$B$8*D16^$B$9*(1-(1-D16^(1/$B$5))^$B$5)^2 -> 4.2552611e-05 | F16: =$B$8*((1-(($B$3*A16)^($B$4-1))*(1+($B$3*A16)^$B$4)^(-1+1/$B$4))^2)/(1+($B$3*A16)^$B$4)^(0.5-(1/(2*$B$4))) -> 4.2552611e-05 | G16: =D16*B16 -> 0.38756246 | I16: 4 | J16: =0.098967*I16 -> 0.395868 | K16: =$J$6+(($J$7-$J$6)/(1+($J$3*I16)^$J$4)^$J$5) -> 0.36225399 | L16: =(K16-$J$6)/($J$7-$J$6) -> 0.97855966 | M16: =$J$8*L16^$J$9*(1-(1-L16^(1/$J$5))^$J$5)^2 -> 1.8994178e-05 | N16: =$J$8*((1-(($J$3*I16)^($J$4-1))*(1+($J$3*I16)^$J$4)^(-1+1/$J$4))^2)/(1+($J$3*I16)^$J$4)^(0.5-(1/(2*$J$4))) -> 1.8994178e-05 | O16: =L16*J16 -> 0.38738046
A17: 5 | B17: =0.098967*A17 -> 0.494835 | C17: =$B$6+(($B$7-$B$6)/(1+($B$3*A17)^$B$4)^$B$5) -> 0.44941214 | D17: =(C17-$B$6)/($B$7-$B$6) -> 0.97058927 | E17: =$B$8*D17^$B$9*(1-(1-D17^(1/$B$5))^$B$5)^2 -> 3.6789115e-05 | F17: =$B$8*((1-(($B$3*A17)^($B$4-1))*(1+($B$3*A17)^$B$4)^(-1+1/$B$4))^2)/(1+($B$3*A17)^$B$4)^(0.5-(1/(2*$B$4))) -> 3.6789115e-05 | G17: =D17*B17 -> 0.48028154 | I17: 5 | J17: =0.098967*I17 -> 0.494835 | K17: =$J$6+(($J$7-$J$6)/(1+($J$3*I17)^$J$4)^$J$5) -> 0.36001262 | L17: =(K17-$J$6)/($J$7-$J$6) -> 0.97019633 | M17: =$J$8*L17^$J$9*(1-(1-L17^(1/$J$5))^$J$5)^2 -> 1.635547e-05 | N17: =$J$8*((1-(($J$3*I17)^($J$4-1))*(1+($J$3*I17)^$J$4)^(-1+1/$J$4))^2)/(1+($J$3*I17)^$J$4)^(0.5-(1/(2*$J$4))) -> 1.635547e-05 | O17: =L17*J17 -> 0.4800871
A18: 6 | B18: =0.098967*A18 -> 0.593802 | C18: =$B$6+(($B$7-$B$6)/(1+($B$3*A18)^$B$4)^$B$5) -> 0.4461109 | D18: =(C18-$B$6)/($B$7-$B$6) -> 0.96141915 | E18: =$B$8*D18^$B$9*(1-(1-D18^(1/$B$5))^$B$5)^2 -> 3.200478e-05 | F18: =$B$8*((1-(($B$3*A18)^($B$4-1))*(1+($B$3*A18)^$B$4)^(-1+1/$B$4))^2)/(1+($B$3*A18)^$B$4)^(0.5-(1/(2*$B$4))) -> 3.200478e-05 | G18: =D18*B18 -> 0.57089262 | I18: 6 | J18: =0.098967*I18 -> 0.593802 | K18: =$J$6+(($J$7-$J$6)/(1+($J$3*I18)^$J$4)^$J$5) -> 0.35759353 | L18: =(K18-$J$6)/($J$7-$J$6) -> 0.96116988 | M18: =$J$8*L18^$J$9*(1-(1-L18^(1/$J$5))^$J$5)^2 -> 1.4186485e-05 | N18: =$J$8*((1-(($J$3*I18)^($J$4-1))*(1+($J$3*I18)^$J$4)^(-1+1/$J$4))^2)/(1+($J$3*I18)^$J$4)^(0.5-(1/(2*$J$4))) -> 1.4186485e-05 | O18: =L18*J18 -> 0.5707446
A19: 8 | B19: =0.098967*A19 -> 0.791736 | C19: =$B$6+(($B$7-$B$6)/(1+($B$3*A19)^$B$4)^$B$5) -> 0.43892786 | D19: =(C19-$B$6)/($B$7-$B$6) -> 0.94146628 | E19: =$B$8*D19^$B$9*(1-(1-D19^(1/$B$5))^$B$5)^2 -> 2.4562305e-05 | F19: =$B$8*((1-(($B$3*A19)^($B$4-1))*(1+($B$3*A19)^$B$4)^(-1+1/$B$4))^2)/(1+($B$3*A19)^$B$4)^(0.5-(1/(2*$B$4))) -> 2.4562305e-05 | G19: =D19*B19 -> 0.74539275 | I19: 8 | J19: =0.098967*I19 -> 0.791736 | K19: =$J$6+(($J$7-$J$6)/(1+($J$3*I19)^$J$4)^$J$5) -> 0.35237779 | L19: =(K19-$J$6)/($J$7-$J$6) -> 0.94170816 | M19: =$J$8*L19^$J$9*(1-(1-L19^(1/$J$5))^$J$5)^2 -> 1.0848644e-05 | N19: =$J$8*((1-(($J$3*I19)^($J$4-1))*(1+($J$3*I19)^$J$4)^(-1+1/$J$4))^2)/(1+($J$3*I19)^$J$4)^(0.5-(1/(2*$J$4))) -> 1.0848644e-05 | O19: =L19*J19 -> 0.74558425
A20: 10 | B20: =0.098967*A20 -> 0.98967 | C20: =$B$6+(($B$7-$B$6)/(1+($B$3*A20)^$B$4)^$B$5) -> 0.43125275 | D20: =(C20-$B$6)/($B$7-$B$6) -> 0.92014654 | E20: =$B$8*D20^$B$9*(1-(1-D20^(1/$B$5))^$B$5)^2 -> 1.9127668e-05 | F20: =$B$8*((1-(($B$3*A20)^($B$4-1))*(1+($B$3*A20)^$B$4)^(-1+1/$B$4))^2)/(1+($B$3*A20)^$B$4)^(0.5-(1/(2*$B$4))) -> 1.9127668e-05 | G20: =D20*B20 -> 0.91064143 | I20: 10 | J20: =0.098967*I20 -> 0.98967 | K20: =$J$6+(($J$7-$J$6)/(1+($J$3*I20)^$J$4)^$J$5) -> 0.34685477 | L20: =(K20-$J$6)/($J$7-$J$6) -> 0.92109989 | M20: =$J$8*L20^$J$9*(1-(1-L20^(1/$J$5))^$J$5)^2 -> 8.4369112e-06 | N20: =$J$8*((1-(($J$3*I20)^($J$4-1))*(1+($J$3*I20)^$J$4)^(-1+1/$J$4))^2)/(1+($J$3*I20)^$J$4)^(0.5-(1/(2*$J$4))) -> 8.4369112e-06 | O20: =L20*J20 -> 0.91158493
A21: 11 | B21: =0.098967*A21 -> 1.088637 | C21: =$B$6+(($B$7-$B$6)/(1+($B$3*A21)^$B$4)^$B$5) -> 0.42731325 | D21: =(C21-$B$6)/($B$7-$B$6) -> 0.90920348 | E21: =$B$8*D21^$B$9*(1-(1-D21^(1/$B$5))^$B$5)^2 -> 1.6957835e-05 | F21: =$B$8*((1-(($B$3*A21)^($B$4-1))*(1+($B$3*A21)^$B$4)^(-1+1/$B$4))^2)/(1+($B$3*A21)^$B$4)^(0.5-(1/(2*$B$4))) -> 1.6957835e-05 | G21: =D21*B21 -> 0.98979255 | I21: 11 | J21: =0.098967*I21 -> 1.088637 | K21: =$J$6+(($J$7-$J$6)/(1+($J$3*I21)^$J$4)^$J$5) -> 0.34403431 | L21: =(K21-$J$6)/($J$7-$J$6) -> 0.91057579 | M21: =$J$8*L21^$J$9*(1-(1-L21^(1/$J$5))^$J$5)^2 -> 7.4794153e-06 | N21: =$J$8*((1-(($J$3*I21)^($J$4-1))*(1+($J$3*I21)^$J$4)^(-1+1/$J$4))^2)/(1+($J$3*I21)^$J$4)^(0.5-(1/(2*$J$4))) -> 7.4794153e-06 | O21: =L21*J21 -> 0.9912865
A22: 13 | B22: =0.098967*A22 -> 1.286571 | C22: =$B$6+(($B$7-$B$6)/(1+($B$3*A22)^$B$4)^$B$5) -> 0.41935392 | D22: =(C22-$B$6)/($B$7-$B$6) -> 0.88709423 | E22: =$B$8*D22^$B$9*(1-(1-D22^(1/$B$5))^$B$5)^2 -> 1.3439858e-05 | F22: =$B$8*((1-(($B$3*A22)^($B$4-1))*(1+($B$3*A22)^$B$4)^(-1+1/$B$4))^2)/(1+($B$3*A22)^$B$4)^(0.5-(1/(2*$B$4))) -> 1.3439858e-05 | G22: =D22*B22 -> 1.1413097 | I22: 13 | J22: =0.098967*I22 -> 1.286571 | K22: =$J$6+(($J$7-$J$6)/(1+($J$3*I22)^$J$4)^$J$5) -> 0.33835798 | L22: =(K22-$J$6)/($J$7-$J$6) -> 0.88939545 | M22: =$J$8*L22^$J$9*(1-(1-L22^(1/$J$5))^$J$5)^2 -> 5.9326724e-06 | N22: =$J$8*((1-(($J$3*I22)^($J$4-1))*(1+($J$3*I22)^$J$4)^(-1+1/$J$4))^2)/(1+($J$3*I22)^$J$4)^(0.5-(1/(2*$J$4))) -> 5.9326724e-06 | O22: =L22*J22 -> 1.1442704
A23: 15 | B23: =0.098967*A23 -> 1.484505 | C23: =$B$6+(($B$7-$B$6)/(1+($B$3*A23)^$B$4)^$B$5) -> 0.41140975 | D23: =(C23-$B$6)/($B$7-$B$6) -> 0.8650271 | E23: =$B$8*D23^$B$9*(1-(1-D23^(1/$B$5))^$B$5)^2 -> 1.0761266e-05 | F23: =$B$8*((1-(($B$3*A23)^($B$4-1))*(1+($B$3*A23)^$B$4)^(-1+1/$B$4))^2)/(1+($B$3*A23)^$B$4)^(0.5-(1/(2*$B$4))) -> 1.0761266e-05 | G23: =D23*B23 -> 1.284137 | I23: 15 | J23: =0.098967*I23 -> 1.484505 | K23: =$J$6+(($J$7-$J$6)/(1+($J$3*I23)^$J$4)^$J$5) -> 0.3327146 | L23: =(K23-$J$6)/($J$7-$J$6) -> 0.86833805 | M23: =$J$8*L23^$J$9*(1-(1-L23^(1/$J$5))^$J$5)^2 -> 4.7587578e-06 | N23: =$J$8*((1-(($J$3*I23)^($J$4-1))*(1+($J$3*I23)^$J$4)^(-1+1/$J$4))^2)/(1+($J$3*I23)^$J$4)^(0.5-(1/(2*$J$4))) -> 4.7587578e-06 | O23: =L23*J23 -> 1.2890522
A24: 17 | B24: =0.098967*A24 -> 1.682439 | C24: =$B$6+(($B$7-$B$6)/(1+($B$3*A24)^$B$4)^$B$5) -> 0.40358802 | D24: =(C24-$B$6)/($B$7-$B$6) -> 0.84330007 | E24: =$B$8*D24^$B$9*(1-(1-D24^(1/$B$5))^$B$5)^2 -> 8.6985872e-06 | F24: =$B$8*((1-(($B$3*A24)^($B$4-1))*(1+($B$3*A24)^$B$4)^(-1+1/$B$4))^2)/(1+($B$3*A24)^$B$4)^(0.5-(1/(2*$B$4))) -> 8.6985872e-06 | G24: =D24*B24 -> 1.4188009 | I24: 17 | J24: =0.098967*I24 -> 1.682439 | K24: =$J$6+(($J$7-$J$6)/(1+($J$3*I24)^$J$4)^$J$5) -> 0.32717334 | L24: =(K24-$J$6)/($J$7-$J$6) -> 0.8476617 | M24: =$J$8*L24^$J$9*(1-(1-L24^(1/$J$5))^$J$5)^2 -> 3.8561572e-06 | N24: =$J$8*((1-(($J$3*I24)^($J$4-1))*(1+($J$3*I24)^$J$4)^(-1+1/$J$4))^2)/(1+($J$3*I24)^$J$4)^(0.5-(1/(2*$J$4))) -> 3.8561572e-06 | O24: =L24*J24 -> 1.4261391
A25: 19 | B25: =0.098967*A25 -> 1.880373 | C25: =$B$6+(($B$7-$B$6)/(1+($B$3*A25)^$B$4)^$B$5) -> 0.39596125 | D25: =(C25-$B$6)/($B$7-$B$6) -> 0.82211458 | E25: =$B$8*D25^$B$9*(1-(1-D25^(1/$B$5))^$B$5)^2 -> 7.0939652e-06 | F25: =$B$8*((1-(($B$3*A25)^($B$4-1))*(1+($B$3*A25)^$B$4)^(-1+1/$B$4))^2)/(1+($B$3*A25)^$B$4)^(0.5-(1/(2*$B$4))) -> 7.0939652e-06 | G25: =D25*B25 -> 1.5458821 | I25: 19 | J25: =0.098967*I25 -> 1.880373 | K25: =$J$6+(($J$7-$J$6)/(1+($J$3*I25)^$J$4)^$J$5) -> 0.32178003 | L25: =(K25-$J$6)/($J$7-$J$6) -> 0.82753741 | M25: =$J$8*L25^$J$9*(1-(1-L25^(1/$J$5))^$J$5)^2 -> 3.1541829e-06 | N25: =$J$8*((1-(($J$3*I25)^($J$4-1))*(1+($J$3*I25)^$J$4)^(-1+1/$J$4))^2)/(1+($J$3*I25)^$J$4)^(0.5-(1/(2*$J$4))) -> 3.1541829e-06 | O25: =L25*J25 -> 1.556079
... A147: 300000 | B147: =0.098967*A147 -> 29690.1 | C147: =$B$6+(($B$7-$B$6)/(1+($B$3*A147)^$B$4)^$B$5) -> 0.10142392 | D147: =(C147-$B$6)/($B$7-$B$6) -> 0.0039553308 | E147: =$B$8*D147^$B$9*(1-(1-D147^(1/$B$5))^$B$5)^2 -> 8.4606692e-20 | F147: =$B$8*((1-(($B$3*A147)^($B$4-1))*(1+($B$3*A147)^$B$4)^(-1+1/$B$4))^2)/(1+($B$3*A147)^$B$4)^(0.5-(1/(2*$B$4))) -> 8.4606691e-20 | G147: =D147*B147 -> 117.43417 | I147: 1000000 | J147: =0.098967*I147 -> 98967 | K147: =$J$6+(($J$7-$J$6)/(1+($J$3*I147)^$J$4)^$J$5) -> 0.10076798 | L147: =(K147-$J$6)/($J$7-$J$6) -> 0.0028655823 | M147: =$J$8*L147^$J$9*(1-(1-L147^(1/$J$5))^$J$5)^2 -> 1.5029035e-21 | N147: =$J$8*((1-(($J$3*I147)^($J$4-1))*(1+($J$3*I147)^$J$4)^(-1+1/$J$4))^2)/(1+($J$3*I147)^$J$4)^(0.5-(1/(2*$J$4))) -> 1.5029035e-21 | O147: =L147*J147 -> 283.59808
A148: 400000 | B148: =0.098967*A148 -> 39586.8 | C148: =$B$6+(($B$7-$B$6)/(1+($B$3*A148)^$B$4)^$B$5) -> 0.10120302 | D148: =(C148-$B$6)/($B$7-$B$6) -> 0.0033417098 | E148: =$B$8*D148^$B$9*(1-(1-D148^(1/$B$5))^$B$5)^2 -> 3.1224254e-20 | F148: =$B$8*((1-(($B$3*A148)^($B$4-1))*(1+($B$3*A148)^$B$4)^(-1+1/$B$4))^2)/(1+($B$3*A148)^$B$4)^(0.5-(1/(2*$B$4))) -> 3.1224253e-20 | G148: =D148*B148 -> 132.2876
A149: 500000 | B149: =0.098967*A149 -> 49483.5 | C149: =$B$6+(($B$7-$B$6)/(1+($B$3*A149)^$B$4)^$B$5) -> 0.10105556 | D149: =(C149-$B$6)/($B$7-$B$6) -> 0.0029321047 | E149: =$B$8*D149^$B$9*(1-(1-D149^(1/$B$5))^$B$5)^2 -> 1.4411159e-20 | F149: =$B$8*((1-(($B$3*A149)^($B$4-1))*(1+($B$3*A149)^$B$4)^(-1+1/$B$4))^2)/(1+($B$3*A149)^$B$4)^(0.5-(1/(2*$B$4))) -> 1.4411159e-20 | G149: =D149*B149 -> 145.0908
A150: 600000 | B150: =0.098967*A150 -> 59380.2 | C150: =$B$6+(($B$7-$B$6)/(1+($B$3*A150)^$B$4)^$B$5) -> 0.1009486 | D150: =(C150-$B$6)/($B$7-$B$6) -> 0.0026349918 | E150: =$B$8*D150^$B$9*(1-(1-D150^(1/$B$5))^$B$5)^2 -> 7.6618901e-21 | F150: =$B$8*((1-(($B$3*A150)^($B$4-1))*(1+($B$3*A150)^$B$4)^(-1+1/$B$4))^2)/(1+($B$3*A150)^$B$4)^(0.5-(1/(2*$B$4))) -> 7.6618897e-21 | G150: =D150*B150 -> 156.46634
A151: 700000 | B151: =0.098967*A151 -> 69276.9 | C151: =$B$6+(($B$7-$B$6)/(1+($B$3*A151)^$B$4)^$B$5) -> 0.10086666 | D151: =(C151-$B$6)/($B$7-$B$6) -> 0.0024074011 | E151: =$B$8*D151^$B$9*(1-(1-D151^(1/$B$5))^$B$5)^2 -> 4.4912301e-21 | F151: =$B$8*((1-(($B$3*A151)^($B$4-1))*(1+($B$3*A151)^$B$4)^(-1+1/$B$4))^2)/(1+($B$3*A151)^$B$4)^(0.5-(1/(2*$B$4))) -> 4.4912303e-21 | G151: =D151*B151 -> 166.77728
A152: 800000 | B152: =0.098967*A152 -> 79173.6 | C152: =$B$6+(($B$7-$B$6)/(1+($B$3*A152)^$B$4)^$B$5) -> 0.10080143 | D152: =(C152-$B$6)/($B$7-$B$6) -> 0.0022262051 | E152: =$B$8*D152^$B$9*(1-(1-D152^(1/$B$5))^$B$5)^2 -> 2.8276342e-21 | F152: =$B$8*((1-(($B$3*A152)^($B$4-1))*(1+($B$3*A152)^$B$4)^(-1+1/$B$4))^2)/(1+($B$3*A152)^$B$4)^(0.5-(1/(2*$B$4))) -> 2.8276337e-21 | G152: =D152*B152 -> 176.25667
A153: 900000 | B153: =0.098967*A153 -> 89070.3 | C153: =$B$6+(($B$7-$B$6)/(1+($B$3*A153)^$B$4)^$B$5) -> 0.10074798 | D153: =(C153-$B$6)/($B$7-$B$6) -> 0.0020777333 | E153: =$B$8*D153^$B$9*(1-(1-D153^(1/$B$5))^$B$5)^2 -> 1.8800948e-21 | F153: =$B$8*((1-(($B$3*A153)^($B$4-1))*(1+($B$3*A153)^$B$4)^(-1+1/$B$4))^2)/(1+($B$3*A153)^$B$4)^(0.5-(1/(2*$B$4))) -> 1.8800946e-21 | G153: =D153*B153 -> 185.06433
A154: 1000000 | B154: =0.098967*A154 -> 98967 | C154: =$B$6+(($B$7-$B$6)/(1+($B$3*A154)^$B$4)^$B$5) -> 0.1007032 | D154: =(C154-$B$6)/($B$7-$B$6) -> 0.0019533313 | E154: =$B$8*D154^$B$9*(1-(1-D154^(1/$B$5))^$B$5)^2 -> 1.3050587e-21 | F154: =$B$8*((1-(($B$3*A154)^($B$4-1))*(1+($B$3*A154)^$B$4)^(-1+1/$B$4))^2)/(1+($B$3*A154)^$B$4)^(0.5-(1/(2*$B$4))) -> 1.3050586e-21 | G154: =D154*B154 -> 193.31534

Sheet SWR_UTU035
A1: Van Genuchten parameters | I1: Van Genuchten parameters
A2: DRYING | I2: WETTING
A3: a (1/cm) = | B3: 0.08 | C3: =B3*10.19 -> 0.8152 | D3: =1/C3 -> 1.2266928 | I3: a = | J3: 0.08 | K3: =J3*10.19 -> 0.8152 | L3: =1/K3 -> 1.2266928
A4: n = | B4: 1.47 | I4: n = | J4: 1.4
A5: m= | B5: =1-1/B4 -> 0.31972789 | I5: m= | J5: =1-1/J4 -> 0.28571429
A6: qr = | B6: 0.089 | I6: qr = | J6: 0.089
A7: qs = | B7: 0.41 | I7: qs = | J7: 0.33
A8: ksat (cm/sec)= | B8: 0.00409 | I8: ksat (cm/sec)= | J8: 6.89e-05
A9: l= | B9: 0.5 | I9: l= | J9: 0.5
A11: HCCC obtained with Van Genuchten-Mualem model | I11: HCCC obtained with Van Genuchten-Mualem model
A13: Suction (cm) | B13: Suction (kPa) | C13: q | D13: Se | E13: k (cm/s) | G13: Suction stress (kPa) | I13: Suction (cm) | J13: Suction (kPa) | K13: q | L13: Se | M13: k (cm/s) | O13: Suction stress (kPa) | R13: Node | S13: Depth | T13: Head M | U13: oisture | V13: K | W13: C | X13: Flux | Y13: Sink | Z13: Kappa | AA13: v/KsTop | AB13: Temp
A14: 1 | B14: =0.098967*A14 -> 0.098967 | C14: =$B$6+(($B$7-$B$6)/(1+($B$3*A14)^$B$4)^$B$5) -> 0.40753449 | D14: =(C14-$B$6)/($B$7-$B$6) -> 0.99231927 | E14: =$B$8*D14^$B$9*(1-(1-D14^(1/$B$5))^$B$5)^2 -> 0.0019806561 | F14: =$B$8*((1-(($B$3*A14)^($B$4-1))*(1+($B$3*A14)^$B$4)^(-1+1/$B$4))^2)/(1+($B$3*A14)^$B$4)^(0.5-(1/(2*$B$4))) -> 0.0019806561 | G14: =D14*B14 -> 0.098206861 | I14: 1 | J14: =0.098967*I14 -> 0.098967 | K14: =$J$6+(($J$7-$J$6)/(1+($J$3*I14)^$J$4)^$J$5) -> 0.328031 | L14: =(K14-$J$6)/($J$7-$J$6) -> 0.99182989 | M14: =$J$8*L14^$J$9*(1-(1-L14^(1/$J$5))^$J$5)^2 -> 2.8006055e-05 | N14: =$J$8*((1-(($J$3*I14)^($J$4-1))*(1+($J$3*I14)^$J$4)^(-1+1/$J$4))^2)/(1+($J$3*I14)^$J$4)^(0.5-(1/(2*$J$4))) -> 2.8006055e-05 | O14: =L14*J14 -> 0.098158429 | S14: [L] | T14: [L] | U14: [-] | V14: [L/T] | W14: [1/L] | X14: [L/T] | Y14: [1/T] | Z14: [-] | AA14: [-] | AB14: [C]
A15: 2 | B15: =0.098967*A15 -> 0.197934 | C15: =$B$6+(($B$7-$B$6)/(1+($B$3*A15)^$B$4)^$B$5) -> 0.40335459 | D15: =(C15-$B$6)/($B$7-$B$6) -> 0.97929778 | E15: =$B$8*D15^$B$9*(1-(1-D15^(1/$B$5))^$B$5)^2 -> 0.0013905501 | F15: =$B$8*((1-(($B$3*A15)^($B$4-1))*(1+($B$3*A15)^$B$4)^(-1+1/$B$4))^2)/(1+($B$3*A15)^$B$4)^(0.5-(1/(2*$B$4))) -> 0.0013905501 | G15: =D15*B15 -> 0.19383633 | I15: 2 | J15: =0.098967*I15 -> 0.197934 | K15: =$J$6+(($J$7-$J$6)/(1+($J$3*I15)^$J$4)^$J$5) -> 0.32495398 | L15: =(K15-$J$6)/($J$7-$J$6) -> 0.97906216 | M15: =$J$8*L15^$J$9*(1-(1-L15^(1/$J$5))^$J$5)^2 -> 1.9122136e-05 | N15: =$J$8*((1-(($J$3*I15)^($J$4-1))*(1+($J$3*I15)^$J$4)^(-1+1/$J$4))^2)/(1+($J$3*I15)^$J$4)^(0.5-(1/(2*$J$4))) -> 1.9122136e-05 | O15: =L15*J15 -> 0.19378969
A16: 4 | B16: =0.098967*A16 -> 0.395868 | C16: =$B$6+(($B$7-$B$6)/(1+($B$3*A16)^$B$4)^$B$5) -> 0.39285356 | D16: =(C16-$B$6)/($B$7-$B$6) -> 0.94658428 | E16: =$B$8*D16^$B$9*(1-(1-D16^(1/$B$5))^$B$5)^2 -> 0.00079122263 | F16: =$B$8*((1-(($B$3*A16)^($B$4-1))*(1+($B$3*A16)^$B$4)^(-1+1/$B$4))^2)/(1+($B$3*A16)^$B$4)^(0.5-(1/(2*$B$4))) -> 0.00079122263 | G16: =D16*B16 -> 0.37472243 | I16: 4 | J16: =0.098967*I16 -> 0.395868 | K16: =$J$6+(($J$7-$J$6)/(1+($J$3*I16)^$J$4)^$J$5) -> 0.31761135 | L16: =(K16-$J$6)/($J$7-$J$6) -> 0.94859483 | M16: =$J$8*L16^$J$9*(1-(1-L16^(1/$J$5))^$J$5)^2 -> 1.066357e-05 | N16: =$J$8*((1-(($J$3*I16)^($J$4-1))*(1+($J$3*I16)^$J$4)^(-1+1/$J$4))^2)/(1+($J$3*I16)^$J$4)^(0.5-(1/(2*$J$4))) -> 1.066357e-05 | O16: =L16*J16 -> 0.37551834 | R16: 1 | S16: 0 | T16: -369.804 | U16: 0.1565 | V16: 9.286e-10 | W16: 8.574e-05 | X16: 1.511e-12 | Y16: 0 | Z16: -1 | AA16: 3.69e-09 | AB16: 20
A17: 5 | B17: =0.098967*A17 -> 0.494835 | C17: =$B$6+(($B$7-$B$6)/(1+($B$3*A17)^$B$4)^$B$5) -> 0.38713307 | D17: =(C17-$B$6)/($B$7-$B$6) -> 0.92876346 | E17: =$B$8*D17^$B$9*(1-(1-D17^(1/$B$5))^$B$5)^2 -> 0.00061882113 | F17: =$B$8*((1-(($B$3*A17)^($B$4-1))*(1+($B$3*A17)^$B$4)^(-1+1/$B$4))^2)/(1+($B$3*A17)^$B$4)^(0.5-(1/(2*$B$4))) -> 0.00061882113 | G17: =D17*B17 -> 0.45958466 | I17: 5 | J17: =0.098967*I17 -> 0.494835 | K17: =$J$6+(($J$7-$J$6)/(1+($J$3*I17)^$J$4)^$J$5) -> 0.31372517 | L17: =(K17-$J$6)/($J$7-$J$6) -> 0.9324696 | M17: =$J$8*L17^$J$9*(1-(1-L17^(1/$J$5))^$J$5)^2 -> 8.3217958e-06 | N17: =$J$8*((1-(($J$3*I17)^($J$4-1))*(1+($J$3*I17)^$J$4)^(-1+1/$J$4))^2)/(1+($J$3*I17)^$J$4)^(0.5-(1/(2*$J$4))) -> 8.3217958e-06 | O17: =L17*J17 -> 0.4614186 | R17: 2 | S17: -0.1342 | T17: -369.927 | U17: 0.1565 | V17: 9.273e-10 | W17: 8.57e-05 | X17: -3.536e-09 | Y17: 0 | Z17: -1 | AA17: -8.65e-06 | AB17: 20
A18: 6 | B18: =0.098967*A18 -> 0.593802 | C18: =$B$6+(($B$7-$B$6)/(1+($B$3*A18)^$B$4)^$B$5) -> 0.38132805 | D18: =(C18-$B$6)/($B$7-$B$6) -> 0.91067928 | E18: =$B$8*D18^$B$9*(1-(1-D18^(1/$B$5))^$B$5)^2 -> 0.00049192882 | F18: =$B$8*((1-(($B$3*A18)^($B$4-1))*(1+($B$3*A18)^$B$4)^(-1+1/$B$4))^2)/(1+($B$3*A18)^$B$4)^(0.5-(1/(2*$B$4))) -> 0.00049192882 | G18: =D18*B18 -> 0.54076318 | I18: 6 | J18: =0.098967*I18 -> 0.593802 | K18: =$J$6+(($J$7-$J$6)/(1+($J$3*I18)^$J$4)^$J$5) -> 0.30982926 | L18: =(K18-$J$6)/($J$7-$J$6) -> 0.91630399 | M18: =$J$8*L18^$J$9*(1-(1-L18^(1/$J$5))^$J$5)^2 -> 6.6200334e-06 | N18: =$J$8*((1-(($J$3*I18)^($J$4-1))*(1+($J$3*I18)^$J$4)^(-1+1/$J$4))^2)/(1+($J$3*I18)^$J$4)^(0.5-(1/(2*$J$4))) -> 6.6200334e-06 | O18: =L18*J18 -> 0.54410314 | R18: 3 | S18: -0.2658 | T18: -370.554 | U18: 0.1564 | V18: 9.208e-10 | W18: 8.544e-05 | X18: -7.057e-09 | Y18: 0 | Z18: -1 | AA18: -1.73e-05 | AB18: 20
A19: 8 | B19: =0.098967*A19 -> 0.791736 | C19: =$B$6+(($B$7-$B$6)/(1+($B$3*A19)^$B$4)^$B$5) -> 0.3698439 | D19: =(C19-$B$6)/($B$7-$B$6) -> 0.87490311 | E19: =$B$8*D19^$B$9*(1-(1-D19^(1/$B$5))^$B$5)^2 -> 0.00032316517 | F19: =$B$8*((1-(($B$3*A19)^($B$4-1))*(1+($B$3*A19)^$B$4)^(-1+1/$B$4))^2)/(1+($B$3*A19)^$B$4)^(0.5-(1/(2*$B$4))) -> 0.00032316517 | G19: =D19*B19 -> 0.69269229 | I19: 8 | J19: =0.098967*I19 -> 0.791736 | K19: =$J$6+(($J$7-$J$6)/(1+($J$3*I19)^$J$4)^$J$5) -> 0.30221292 | L19: =(K19-$J$6)/($J$7-$J$6) -> 0.88470092 | M19: =$J$8*L19^$J$9*(1-(1-L19^(1/$J$5))^$J$5)^2 -> 4.3787984e-06 | N19: =$J$8*((1-(($J$3*I19)^($J$4-1))*(1+($J$3*I19)^$J$4)^(-1+1/$J$4))^2)/(1+($J$3*I19)^$J$4)^(0.5-(1/(2*$J$4))) -> 4.3787984e-06 | O19: =L19*J19 -> 0.70044956 | R19: 4 | S19: -0.3948 | T19: -371.669 | U19: 0.1563 | V19: 9.092e-10 | W19: 8.5e-05 | X19: -1.054e-08 | Y19: 0 | Z19: -1 | AA19: -2.58e-05 | AB19: 20
A20: 10 | B20: =0.098967*A20 -> 0.98967 | C20: =$B$6+(($B$7-$B$6)/(1+($B$3*A20)^$B$4)^$B$5) -> 0.35888077 | D20: =(C20-$B$6)/($B$7-$B$6) -> 0.84075006 | E20: =$B$8*D20^$B$9*(1-(1-D20^(1/$B$5))^$B$5)^2 -> 0.00022137267 | F20: =$B$8*((1-(($B$3*A20)^($B$4-1))*(1+($B$3*A20)^$B$4)^(-1+1/$B$4))^2)/(1+($B$3*A20)^$B$4)^(0.5-(1/(2*$B$4))) -> 0.00022137267 | G20: =D20*B20 -> 0.83206511 | I20: 10 | J20: =0.098967*I20 -> 0.98967 | K20: =$J$6+(($J$7-$J$6)/(1+($J$3*I20)^$J$4)^$J$5) -> 0.29500741 | L20: =(K20-$J$6)/($J$7-$J$6) -> 0.85480255 | M20: =$J$8*L20^$J$9*(1-(1-L20^(1/$J$5))^$J$5)^2 -> 3.0326175e-06 | N20: =$J$8*((1-(($J$3*I20)^($J$4-1))*(1+($J$3*I20)^$J$4)^(-1+1/$J$4))^2)/(1+($J$3*I20)^$J$4)^(0.5-(1/(2*$J$4))) -> 3.0326175e-06 | O20: =L20*J20 -> 0.84597244 | R20: 5 | S20: -0.5212 | T20: -373.269 | U20: 0.1562 | V20: 8.925e-10 | W20: 8.435e-05 | X20: -1.401e-08 | Y20: 0 | Z20: -1 | AA20: -3.43e-05 | AB20: 20
A21: 11 | B21: =0.098967*A21 -> 1.088637 | C21: =$B$6+(($B$7-$B$6)/(1+($B$3*A21)^$B$4)^$B$5) -> 0.35366219 | D21: =(C21-$B$6)/($B$7-$B$6) -> 0.82449281 | E21: =$B$8*D21^$B$9*(1-(1-D21^(1/$B$5))^$B$5)^2 -> 0.0001856536 | F21: =$B$8*((1-(($B$3*A21)^($B$4-1))*(1+($B$3*A21)^$B$4)^(-1+1/$B$4))^2)/(1+($B$3*A21)^$B$4)^(0.5-(1/(2*$B$4))) -> 0.0001856536 | G21: =D21*B21 -> 0.89757338 | I21: 11 | J21: =0.098967*I21 -> 1.088637 | K21: =$J$6+(($J$7-$J$6)/(1+($J$3*I21)^$J$4)^$J$5) -> 0.29158898 | L21: =(K21-$J$6)/($J$7-$J$6) -> 0.84061816 | M21: =$J$8*L21^$J$9*(1-(1-L21^(1/$J$5))^$J$5)^2 -> 2.5594194e-06 | N21: =$J$8*((1-(($J$3*I21)^($J$4-1))*(1+($J$3*I21)^$J$4)^(-1+1/$J$4))^2)/(1+($J$3*I21)^$J$4)^(0.5-(1/(2*$J$4))) -> 2.5594194e-06 | O21: =L21*J21 -> 0.91512803 | R21: 6 | S21: -0.645 | T21: -375.358 | U21: 0.156 | V21: 8.707e-10 | W21: 8.352e-05 | X21: -1.748e-08 | Y21: 0 | Z21: -1 | AA21: -4.27e-05 | AB21: 20
A22: 13 | B22: =0.098967*A22 -> 1.286571 | C22: =$B$6+(($B$7-$B$6)/(1+($B$3*A22)^$B$4)^$B$5) -> 0.34379848 | D22: =(C22-$B$6)/($B$7-$B$6) -> 0.79376472 | E22: =$B$8*D22^$B$9*(1-(1-D22^(1/$B$5))^$B$5)^2 -> 0.00013358556 | F22: =$B$8*((1-(($B$3*A22)^($B$4-1))*(1+($B$3*A22)^$B$4)^(-1+1/$B$4))^2)/(1+($B$3*A22)^$B$4)^(0.5-(1/(2*$B$4))) -> 0.00013358556 | G22: =D22*B22 -> 1.0212347 | I22: 13 | J22: =0.098967*I22 -> 1.286571 | K22: =$J$6+(($J$7-$J$6)/(1+($J$3*I22)^$J$4)^$J$5) -> 0.28513498 | L22: =(K22-$J$6)/($J$7-$J$6) -> 0.81383807 | M22: =$J$8*L22^$J$9*(1-(1-L22^(1/$J$5))^$J$5)^2 -> 1.866607e-06 | N22: =$J$8*((1-(($J$3*I22)^($J$4-1))*(1+($J$3*I22)^$J$4)^(-1+1/$J$4))^2)/(1+($J$3*I22)^$J$4)^(0.5-(1/(2*$J$4))) -> 1.866607e-06 | O22: =L22*J22 -> 1.0470605 | R22: 7 | S22: -0.7663 | T22: -377.958 | U22: 0.1557 | V22: 8.436e-10 | W22: 8.247e-05 | X22: -2.096e-08 | Y22: 0 | Z22: -1 | AA22: -5.12e-05 | AB22: 20
A23: 15 | B23: =0.098967*A23 -> 1.484505 | C23: =$B$6+(($B$7-$B$6)/(1+($B$3*A23)^$B$4)^$B$5) -> 0.33470087 | D23: =(C23-$B$6)/($B$7-$B$6) -> 0.76542328 | E23: =$B$8*D23^$B$9*(1-(1-D23^(1/$B$5))^$B$5)^2 -> 9.8715306e-05 | F23: =$B$8*((1-(($B$3*A23)^($B$4-1))*(1+($B$3*A23)^$B$4)^(-1+1/$B$4))^2)/(1+($B$3*A23)^$B$4)^(0.5-(1/(2*$B$4))) -> 9.8715306e-05 | G23: =D23*B23 -> 1.1362747 | I23: 15 | J23: =0.098967*I23 -> 1.484505 | K23: =$J$6+(($J$7-$J$6)/(1+($J$3*I23)^$J$4)^$J$5) -> 0.27917981 | L23: =(K23-$J$6)/($J$7-$J$6) -> 0.78912783 | M23: =$J$8*L23^$J$9*(1-(1-L23^(1/$J$5))^$J$5)^2 -> 1.3987297e-06 | N23: =$J$8*((1-(($J$3*I23)^($J$4-1))*(1+($J$3*I23)^$J$4)^(-1+1/$J$4))^2)/(1+($J$3*I23)^$J$4)^(0.5-(1/(2*$J$4))) -> 1.3987297e-06 | O23: =L23*J23 -> 1.1714642 | R23: 8 | S23: -0.8849 | T23: -381.099 | U23: 0.1555 | V23: 8.109e-10 | W23: 8.121e-05 | X23: -2.448e-08 | Y23: 0 | Z23: -1 | AA23: -5.98e-05 | AB23: 20
A24: 17 | B24: =0.098967*A24 -> 1.682439 | C24: =$B$6+(($B$7-$B$6)/(1+($B$3*A24)^$B$4)^$B$5) -> 0.32633366 | D24: =(C24-$B$6)/($B$7-$B$6) -> 0.7393572 | E24: =$B$8*D24^$B$9*(1-(1-D24^(1/$B$5))^$B$5)^2 -> 7.4642343e-05 | F24: =$B$8*((1-(($B$3*A24)^($B$4-1))*(1+($B$3*A24)^$B$4)^(-1+1/$B$4))^2)/(1+($B$3*A24)^$B$4)^(0.5-(1/(2*$B$4))) -> 7.4642343e-05 | G24: =D24*B24 -> 1.2439234 | I24: 17 | J24: =0.098967*I24 -> 1.682439 | K24: =$J$6+(($J$7-$J$6)/(1+($J$3*I24)^$J$4)^$J$5) -> 0.27369211 | L24: =(K24-$J$6)/($J$7-$J$6) -> 0.76635728 | M24: =$J$8*L24^$J$9*(1-(1-L24^(1/$J$5))^$J$5)^2 -> 1.0724584e-06 | N24: =$J$8*((1-(($J$3*I24)^($J$4-1))*(1+($J$3*I24)^$J$4)^(-1+1/$J$4))^2)/(1+($J$3*I24)^$J$4)^(0.5-(1/(2*$J$4))) -> 1.0724584e-06 | O24: =L24*J24 -> 1.2893494 | R24: 9 | S24: -1.001 | T24: -384.835 | U24: 0.1551 | V24: 7.72e-10 | W24: 7.971e-05 | X24: -2.805e-08 | Y24: 0 | Z24: -1 | AA24: -6.86e-05 | AB24: 20
A25: 19 | B25: =0.098967*A25 -> 1.880373 | C25: =$B$6+(($B$7-$B$6)/(1+($B$3*A25)^$B$4)^$B$5) -> 0.31864116 | D25: =(C25-$B$6)/($B$7-$B$6) -> 0.71539302 | E25: =$B$8*D25^$B$9*(1-(1-D25^(1/$B$5))^$B$5)^2 -> 5.7579674e-05 | F25: =$B$8*((1-(($B$3*A25)^($B$4-1))*(1+($B$3*A25)^$B$4)^(-1+1/$B$4))^2)/(1+($B$3*A25)^$B$4)^(0.5-(1/(2*$B$4))) -> 5.7579674e-05 | G25: =D25*B25 -> 1.3452057 | I25: 19 | J25: =0.098967*I25 -> 1.880373 | K25: =$J$6+(($J$7-$J$6)/(1+($J$3*I25)^$J$4)^$J$5) -> 0.26863236 | L25: =(K25-$J$6)/($J$7-$J$6) -> 0.74536249 | M25: =$J$8*L25^$J$9*(1-(1-L25^(1/$J$5))^$J$5)^2 -> 8.3865543e-07 | N25: =$J$8*((1-(($J$3*I25)^($J$4-1))*(1+($J$3*I25)^$J$4)^(-1+1/$J$4))^2)/(1+($J$3*I25)^$J$4)^(0.5-(1/(2*$J$4))) -> 8.3865543e-07 | O25: =L25*J25 -> 1.4015595 | R25: 10 | S25: -1.1145 | T25: -389.171 | U25: 0.1548 | V25: 7.514e-10 | W25: 7.864e-05 | X25: -3.114e-08 | Y25: 0 | Z25: -1 | AA25: -7.61e-05 | AB25: 20
